Workbook

Sheet Sheet1
A1: Electrode | B1: Inlet flow rate | C1: Flow rate (ml min-1) | D1: Catholyte | E1: Anolyte | F1: Membrane | G1: Applied current / A | H1: Time | I1: Duration / h | J1: area(H2) | K1: area(CO) | L1: area(CO2) | M1: area(CH4) | N1: area(O2) | O1: area(N2) | P1: c(H2) | Q1: c(CO) | R1: c(CO2) | S1: c(O2) | T1: FE(H2) | U1: FE(CO) | V1: FE(CH4) | W1: Total FE | X1: Carbon efficiency
A2: Ag60 GDE in PTFE holder | B2: 60 | C2: =+'Flow rate'!E1 -> 58.815907 | D2: 0.3 M K2SO4 | E2: 0.05 M H2SO4 | F2: CCM-CEM | G2: 0 | H2: 45443.789 | I2: 0 | J2: 0 | K2: 0 | L2: 0 | N2: 0 | O2: 0 | P2: 0 | Q2: 0 | R2: 0 | S2: 0 | T2: 0 | U2: 0 | W2: 0 | X2: 0 | Y2: 0
A3: Ag60 GDE in PTFE holder | B3: 60 | C3: =+'Flow rate'!E2 -> 60.413028 | D3: 0.3 M K2SO4 | E3: 0.05 M H2SO4 | F3: CCM-CEM | G3: -0.125 | H3: 45443.793 | I3: 0.085318611 | J3: 0.38340232 | K3: 0 | L3: 106.86504 | N3: 0.022603825 | O3: 0.05765329 | P3: =+J3/SUM($J3:$O3) -> 0.0035722254 | Q3: =+K3/SUM($J3:$O3) -> 0 | R3: =+L3/SUM($J3:$O3) -> 0.99568001 | S3: =+N3/SUM($J3:$O3) -> 0.00021060372 | T3: =+P3*C3/1000/60/24.3*2*96485/-1/G3 -> 0.2285029 | U3: =+Q3*C3/1000/60/24.3*2*96485/-1/G3 -> 0 | W3: =T3+U3 -> 0.2285029 | X3: 0
A4: Ag60 GDE in PTFE holder | B4: 60 | C4: =+'Flow rate'!E3 -> 61.367047 | D4: 0.3 M K2SO4 | E4: 0.05 M H2SO4 | F4: CCM-CEM | G4: -0.125 | H4: 45443.808 | I4: 0.46059639 | J4: 1.5726833 | K4: 0 | L4: 105.30371 | N4: 0.014529462 | O4: 0.045548084 | P4: =+J4/SUM($J4:$O4) -> 0.014706707 | Q4: =+K4/SUM($J4:$O4) -> 0 | R4: =+L4/SUM($J4:$O4) -> 0.98473149 | S4: =+N4/SUM($J4:$O4) -> 0.00013587004 | T4: =+P4*C4/1000/60/24.3*2*96485/-1/G4 -> 0.9555929 | U4: =+Q4*C4/1000/60/24.3*2*96485/-1/G4 -> 0 | W4: =T4+U4 -> 0.9555929 | X4: 0 | Y4: 105.3037
A5: Ag60 GDE in PTFE holder | B5: 60 | C5: =+'Flow rate'!E4 -> 61.254046 | D5: 0.3 M K2SO4 | E5: 0.05 M H2SO4 | F5: CCM-CEM | G5: -0.125 | H5: 45443.824 | I5: 0.83559639 | J5: 1.5842559 | K5: 0 | L5: 105.50935 | N5: 0.010752572 | O5: 0.036534103 | P5: =+J5/SUM($J5:$O5) -> 0.01478666 | Q5: =+K5/SUM($J5:$O5) -> 0 | R5: =+L5/SUM($J5:$O5) -> 0.98477199 | S5: =+N5/SUM($J5:$O5) -> 0.00010035918 | T5: =+P5*C5/1000/60/24.3*2*96485/-1/G5 -> 0.95901881 | U5: =+Q5*C5/1000/60/24.3*2*96485/-1/G5 -> 0 | W5: =T5+U5 -> 0.95901881 | X5: 0
A6: Ag60 GDE in PTFE holder | B6: 60 | C6: =+'Flow rate'!E5 -> 61.057261 | D6: 0.3 M K2SO4 | E6: 0.05 M H2SO4 | F6: CCM-CEM | G6: -0.125 | H6: 45443.84 | I6: 1.2114297 | J6: 1.5769961 | K6: 0 | L6: 105.39534 | N6: 0.0052725827 | O6: 0.022575898 | P6: =+J6/SUM($J6:$O6) -> 0.014738255 | Q6: =+K6/SUM($J6:$O6) -> 0 | R6: =+L6/SUM($J6:$O6) -> 0.98500148 | S6: =+N6/SUM($J6:$O6) -> 4.9276388e-05 | T6: =+P6*C6/1000/60/24.3*2*96485/-1/G6 -> 0.95280858 | U6: =+Q6*C6/1000/60/24.3*2*96485/-1/G6 -> 0 | W6: =T6+U6 -> 0.95280858 | X6: 0 | Y6: 105.3953
A7: Ag60 GDE in PTFE holder | B7: 60 | C7: =+'Flow rate'!E6 -> 61.700919 | D7: 0.3 M K2SO4 | E7: 0.05 M H2SO4 | F7: CCM-CEM | G7: -0.125 | H7: 45443.855 | I7: 1.5869853 | J7: 1.6223909 | K7: 0 | L7: 105.36056 | N7: 0.0035226433 | O7: 0.020550152 | P7: =+J7/SUM($J7:$O7) -> 0.015161537 | Q7: =+K7/SUM($J7:$O7) -> 0 | R7: =+L7/SUM($J7:$O7) -> 0.9846135 | S7: =+N7/SUM($J7:$O7) -> 3.291974e-05 | T7: =+P7*C7/1000/60/24.3*2*96485/-1/G7 -> 0.990506 | U7: =+Q7*C7/1000/60/24.3*2*96485/-1/G7 -> 0 | W7: =T7+U7 -> 0.990506 | X7: 0
A8: Ag60 GDE in PTFE holder | B8: 60 | C8: =+'Flow rate'!E7 -> 61.782924 | D8: 0.3 M K2SO4 | E8: 0.05 M H2SO4 | F8: CCM-CEM | G8: -0.125 | H8: 45443.871 | I8: 1.9622631 | J8: 1.6341582 | K8: 0 | L8: 105.07096 | N8: 0.0061116808 | O8: 0.033857305 | P8: =+J8/SUM($J8:$O8) -> 0.015308978 | Q8: =+K8/SUM($J8:$O8) -> 0 | R8: =+L8/SUM($J8:$O8) -> 0.98431659 | S8: =+N8/SUM($J8:$O8) -> 5.7254916e-05 | T8: =+P8*C8/1000/60/24.3*2*96485/-1/G8 -> 1.0014677 | U8: =+Q8*C8/1000/60/24.3*2*96485/-1/G8 -> 0 | W8: =T8+U8 -> 1.0014677 | X8: 0 | Y8: 105.071
A9: Ag60 GDE in PTFE holder | B9: 60 | C9: =+'Flow rate'!E8 -> 63.533286 | D9: 0.3 M K2SO4 | E9: 0.05 M H2SO4 | F9: CCM-CEM | G9: -0.27 | H9: 45443.887 | I9: 2.3372631 | J9: 3.2224944 | K9: 0 | L9: 103.35033 | N9: 0 | O9: 0.014435454 | P9: =+J9/SUM($J9:$O9) -> 0.03023339 | Q9: =+K9/SUM($J9:$O9) -> 0 | R9: =+L9/SUM($J9:$O9) -> 0.96963118 | S9: =+N9/SUM($J9:$O9) -> 0 | T9: =+P9*C9/1000/60/24.3*2*96485/-1/G9 -> 0.94157881 | U9: =+Q9*C9/1000/60/24.3*2*96485/-1/G9 -> 0 | W9: =T9+U9 -> 0.94157881 | X9: 0
A10: Ag60 GDE in PTFE holder | B10: 60 | C10: =+'Flow rate'!E9 -> 63.664311 | D10: 0.3 M K2SO4 | E10: 0.05 M H2SO4 | F10: CCM-CEM | G10: -0.27 | H10: 45443.902 | I10: 2.7128186 | J10: 3.3242813 | K10: 0 | L10: 103.08796 | N10: 0 | O10: 0.015834649 | P10: =+J10/SUM($J10:$O10) -> 0.031235003 | Q10: =+K10/SUM($J10:$O10) -> 0 | R10: =+L10/SUM($J10:$O10) -> 0.96861621 | S10: =+N10/SUM($J10:$O10) -> 0 | T10: =+P10*C10/1000/60/24.3*2*96485/-1/G10 -> 0.97477888 | U10: =+Q10*C10/1000/60/24.3*2*96485/-1/G10 -> 0 | W10: =T10+U10 -> 0.97477888 | X10: 0 | Y10: 103.088
A11: Ag60 GDE in PTFE holder | B11: 60 | C11: =+'Flow rate'!E10 -> 63.458614 | D11: 0.3 M K2SO4 | E11: 0.05 M H2SO4 | F11: CCM-CEM | G11: -0.27 | H11: 45443.925 | I11: 3.2630964 | J11: 3.3512282 | K11: 0 | L11: 103.58233 | N11: 0 | O11: 0.013753746 | P11: =+J11/SUM($J11:$O11) -> 0.03133532 | Q11: =+K11/SUM($J11:$O11) -> 0 | R11: =+L11/SUM($J11:$O11) -> 0.96853608 | S11: =+N11/SUM($J11:$O11) -> 0 | T11: =+P11*C11/1000/60/24.3*2*96485/-1/G11 -> 0.97474995 | U11: =+Q11*C11/1000/60/24.3*2*96485/-1/G11 -> 0 | W11: =T11+U11 -> 0.97474995 | X11: 0
A12: Ag60 GDE in PTFE holder | B12: 60 | C12: =+'Flow rate'!E11 -> 63.347826 | D12: 0.3 M K2SO4 | E12: 0.05 M H2SO4 | F12: CCM-CEM | G12: -0.27 | H12: 45443.941 | I12: 3.6383742 | J12: 3.3632653 | K12: 0 | L12: 103.65645 | N12: 0.001759304 | O12: 0.026825395 | P12: =+J12/SUM($J12:$O12) -> 0.031418204 | Q12: =+K12/SUM($J12:$O12) -> 0 | R12: =+L12/SUM($J12:$O12) -> 0.96831477 | S12: =+N12/SUM($J12:$O12) -> 1.6434675e-05 | T12: =+P12*C12/1000/60/24.3*2*96485/-1/G12 -> 0.97562197 | U12: =+Q12*C12/1000/60/24.3*2*96485/-1/G12 -> 0 | W12: =T12+U12 -> 0.97562197 | X12: 0 | Y12: 103.6565
A13: Ag60 GDE in PTFE holder | B13: 60 | C13: =+'Flow rate'!E12 -> 64.646482 | D13: 0.3 M K2SO4 | E13: 0.05 M H2SO4 | F13: CCM-CEM | G13: -0.52 | H13: 45443.956 | I13: 4.0130964 | J13: 3.3604475 | K13: 0 | L13: 103.56527 | N13: 0 | O13: 0.010607979 | P13: =+J13/SUM($J13:$O13) -> 0.031424753 | Q13: =+K13/SUM($J13:$O13) -> 0 | R13: =+L13/SUM($J13:$O13) -> 0.96847605 | S13: =+N13/SUM($J13:$O13) -> 0 | T13: =+P13*C13/1000/60/24.3*2*96485/-1/G13 -> 0.51706567 | U13: =+Q13*C13/1000/60/24.3*2*96485/-1/G13 -> 0 | W13: =T13+U13 -> 0.51706567 | X13: 0
A14: Ag60 GDE in PTFE holder | B14: 60 | C14: =+'Flow rate'!E13 -> 65.777474 | D14: 0.3 M K2SO4 | E14: 0.05 M H2SO4 | F14: CCM-CEM | G14: -0.52 | H14: 45443.972 | I14: 4.3883742 | J14: 5.8894148 | K14: 0 | L14: 100.3218 | N14: 0.0017421094 | O14: 0.032863491 | P14: =+J14/SUM($J14:$O14) -> 0.055431969 | Q14: =+K14/SUM($J14:$O14) -> 0 | R14: =+L14/SUM($J14:$O14) -> 0.94424232 | S14: =+N14/SUM($J14:$O14) -> 1.6396969e-05 | T14: =+P14*C14/1000/60/24.3*2*96485/-1/G14 -> 0.92803942 | U14: =+Q14*C14/1000/60/24.3*2*96485/-1/G14 -> 0 | W14: =T14+U14 -> 0.92803942 | X14: 0 | Y14: 100.3218
A15: Ag60 GDE in PTFE holder | B15: 60 | C15: =+'Flow rate'!E14 -> 65.957443 | D15: 0.3 M K2SO4 | E15: 0.05 M H2SO4 | F15: CCM-CEM | G15: -0.52 | H15: 45443.988 | I15: 4.7636519 | J15: 5.9946512 | K15: 0 | L15: 100.22773 | N15: 0 | O15: 0.0078572942 | P15: =+J15/SUM($J15:$O15) -> 0.056430741 | Q15: =+K15/SUM($J15:$O15) -> 0 | R15: =+L15/SUM($J15:$O15) -> 0.94349529 | S15: =+N15/SUM($J15:$O15) -> 0 | T15: =+P15*C15/1000/60/24.3*2*96485/-1/G15 -> 0.94734571 | U15: =+Q15*C15/1000/60/24.3*2*96485/-1/G15 -> 0 | W15: =T15+U15 -> 0.94734571 | X15: 0
A16: Ag60 GDE in PTFE holder | B16: 60 | C16: =+'Flow rate'!E15 -> 65.615141 | D16: 0.3 M K2SO4 | E16: 0.05 M H2SO4 | F16: CCM-CEM | G16: -0.52 | H16: 45444.003 | I16: 5.1389297 | J16: 6.0302358 | K16: 0 | L16: 100.13291 | N16: 0 | O16: 0.0082893269 | P16: =+J16/SUM($J16:$O16) -> 0.056797157 | Q16: =+K16/SUM($J16:$O16) -> 0 | R16: =+L16/SUM($J16:$O16) -> 0.94312477 | S16: =+N16/SUM($J16:$O16) -> 0 | T16: =+P16*C16/1000/60/24.3*2*96485/-1/G16 -> 0.94854861 | U16: =+Q16*C16/1000/60/24.3*2*96485/-1/G16 -> 0 | W16: =T16+U16 -> 0.94854861 | X16: 0 | Y16: 100.1329
A17: Ag60 GDE in PTFE holder | B17: 60 | C17: =+'Flow rate'!E16 -> 65.324659 | D17: 0.3 M K2SO4 | E17: 0.05 M H2SO4 | F17: CCM-CEM | G17: -0.52 | H17: 45444.019 | I17: 5.5142075 | J17: 6.0390705 | K17: 0 | L17: 100.07043 | N17: 0 | O17: 0.011770365 | P17: =+J17/SUM($J17:$O17) -> 0.056907257 | Q17: =+K17/SUM($J17:$O17) -> 0 | R17: =+L17/SUM($J17:$O17) -> 0.94298183 | S17: =+N17/SUM($J17:$O17) -> 0 | T17: =+P17*C17/1000/60/24.3*2*96485/-1/G17 -> 0.94617993 | U17: =+Q17*C17/1000/60/24.3*2*96485/-1/G17 -> 0 | W17: =T17+U17 -> 0.94617993 | X17: 0
A18: Ag60 GDE in PTFE holder | B18: 60 | C18: =+'Flow rate'!E17 -> 65.369837 | D18: 0.3 M K2SO4 | E18: 0.05 M H2SO4 | F18: CCM-CEM | G18: -0.52 | H18: 45444.035 | I18: 5.8892075 | J18: 6.0512653 | K18: 0 | L18: 100.07371 | N18: 0 | O18: 0.0070294419 | P18: =+J18/SUM($J18:$O18) -> 0.057016403 | Q18: =+K18/SUM($J18:$O18) -> 0 | R18: =+L18/SUM($J18:$O18) -> 0.94291736 | S18: =+N18/SUM($J18:$O18) -> 0 | T18: =+P18*C18/1000/60/24.3*2*96485/-1/G18 -> 0.9486503 | U18: =+Q18*C18/1000/60/24.3*2*96485/-1/G18 -> 0 | W18: =T18+U18 -> 0.9486503 | X18: 0 | Y18: 100.0737
A19: Ag60 GDE in PTFE holder | B19: 60 | C19: =+'Flow rate'!E18 -> 67.931335 | D19: 0.3 M K2SO4 | E19: 0.05 M H2SO4 | F19: CCM-CEM | G19: -0.77 | H19: 45444.058 | I19: 6.4394853 | J19: 8.5433352 | K19: 0 | L19: 97.000988 | N19: 0 | O19: 0.0076171187 | P19: =+J19/SUM($J19:$O19) -> 0.080939632 | Q19: =+K19/SUM($J19:$O19) -> 0 | R19: =+L19/SUM($J19:$O19) -> 0.9189882 | S19: =+N19/SUM($J19:$O19) -> 0 | T19: =+P19*C19/1000/60/24.3*2*96485/-1/G19 -> 0.94508947 | U19: =+Q19*C19/1000/60/24.3*2*96485/-1/G19 -> 0 | W19: =T19+U19 -> 0.94508947 | X19: 0
A20: Ag60 GDE in PTFE holder | B20: 60 | C20: =+'Flow rate'!E19 -> 67.372111 | D20: 0.3 M K2SO4 | E20: 0.05 M H2SO4 | F20: CCM-CEM | G20: -0.77 | H20: 45444.073 | I20: 6.8147631 | J20: 8.636632 | K20: 0 | L20: 96.793364 | N20: 0 | O20: 0.0076843067 | P20: =+J20/SUM($J20:$O20) -> 0.081912197 | Q20: =+K20/SUM($J20:$O20) -> 0 | R20: =+L20/SUM($J20:$O20) -> 0.91801492 | S20: =+N20/SUM($J20:$O20) -> 0 | T20: =+P20*C20/1000/60/24.3*2*96485/-1/G20 -> 0.94857195 | U20: =+Q20*C20/1000/60/24.3*2*96485/-1/G20 -> 0 | W20: =T20+U20 -> 0.94857195 | X20: 0 | Y20: 96.7934
A21: Ag60 GDE in PTFE holder | B21: 60 | C21: =+'Flow rate'!E20 -> 67.60469 | D21: 0.3 M K2SO4 | E21: 0.05 M H2SO4 | F21: CCM-CEM | G21: -0.77 | H21: 45444.089 | I21: 7.1894853 | J21: 8.6384696 | K21: 0 | L21: 96.648916 | N21: 0 | O21: 0.0071260791 | P21: =+J21/SUM($J21:$O21) -> 0.082041024 | Q21: =+K21/SUM($J21:$O21) -> 0 | R21: =+L21/SUM($J21:$O21) -> 0.9178913 | S21: =+N21/SUM($J21:$O21) -> 0 | T21: =+P21*C21/1000/60/24.3*2*96485/-1/G21 -> 0.95334358 | U21: =+Q21*C21/1000/60/24.3*2*96485/-1/G21 -> 0 | W21: =T21+U21 -> 0.95334358 | X21: 0
A22: Ag60 GDE in PTFE holder | B22: 60 | C22: =+'Flow rate'!E21 -> 67.366549 | D22: 0.3 M K2SO4 | E22: 0.05 M H2SO4 | F22: CCM-CEM | G22: -0.77 | H22: 45444.104 | I22: 7.5650408 | J22: 8.661759 | K22: 0 | L22: 96.717164 | N22: 0 | O22: 0.0057170977 | P22: =+J22/SUM($J22:$O22) -> 0.082191854 | Q22: =+K22/SUM($J22:$O22) -> 0 | R22: =+L22/SUM($J22:$O22) -> 0.9177539 | S22: =+N22/SUM($J22:$O22) -> 0 | T22: =+P22*C22/1000/60/24.3*2*96485/-1/G22 -> 0.9517319 | U22: =+Q22*C22/1000/60/24.3*2*96485/-1/G22 -> 0 | W22: =T22+U22 -> 0.9517319 | X22: 0 | Y22: 96.7172
A23: Ag60 GDE in PTFE holder | B23: 60 | C23: =+'Flow rate'!E22 -> 67.288673 | D23: 0.3 M K2SO4 | E23: 0.05 M H2SO4 | F23: CCM-CEM | G23: -0.77 | H23: 45444.12 | I23: 7.9403186 | J23: 8.6630198 | K23: 0 | L23: 96.741525 | N23: 0 | O23: 0.011117893 | P23: =+J23/SUM($J23:$O23) -> 0.082179627 | Q23: =+K23/SUM($J23:$O23) -> 0 | R23: =+L23/SUM($J23:$O23) -> 0.91771491 | S23: =+N23/SUM($J23:$O23) -> 0 | T23: =+P23*C23/1000/60/24.3*2*96485/-1/G23 -> 0.95049027 | U23: =+Q23*C23/1000/60/24.3*2*96485/-1/G23 -> 0 | W23: =T23+U23 -> 0.95049027 | X23: 0
A24: Ag60 GDE in PTFE holder | B24: 60 | C24: =+'Flow rate'!E23 -> 69.794351 | D24: 0.3 M K2SO4 | E24: 0.05 M H2SO4 | F24: CCM-CEM | G24: -1.1 | H24: 45444.136 | I24: 8.3153186 | J24: 10.934595 | K24: 0 | L24: 93.904726 | N24: 0 | O24: 0.0033936743 | P24: =+J24/SUM($J24:$O24) -> 0.10429523 | Q24: =+K24/SUM($J24:$O24) -> 0 | R24: =+L24/SUM($J24:$O24) -> 0.8956724 | S24: =+N24/SUM($J24:$O24) -> 0 | T24: =+P24*C24/1000/60/24.3*2*96485/-1/G24 -> 0.87583903 | U24: =+Q24*C24/1000/60/24.3*2*96485/-1/G24 -> 0 | W24: =T24+U24 -> 0.87583903 | X24: 0 | Y24: 93.9047
A25: Ag60 GDE in PTFE holder | B25: 60 | C25: =+'Flow rate'!E24 -> 69.541418 | D25: 0.3 M K2SO4 | E25: 0.05 M H2SO4 | F25: CCM-CEM | G25: -1.1 | H25: 45444.151 | I25: 8.6903186 | J25: 11.089262 | K25: 0 | L25: 93.712578 | N25: 0 | O25: 0.004761637 | P25: =+J25/SUM($J25:$O25) -> 0.10580691 | Q25: =+K25/SUM($J25:$O25) -> 0 | R25: =+L25/SUM($J25:$O25) -> 0.89414766 | S25: =+N25/SUM($J25:$O25) -> 0 | T25: =+P25*C25/1000/60/24.3*2*96485/-1/G25 -> 0.88531363 | U25: =+Q25*C25/1000/60/24.3*2*96485/-1/G25 -> 0 | W25: =T25+U25 -> 0.88531363 | X25: 0
A26: Ag60 GDE in PTFE holder | B26: 60 | C26: =+'Flow rate'!E25 -> 69.496482 | D26: 0.3 M K2SO4 | E26: 0.05 M H2SO4 | F26: CCM-CEM | G26: -1.1 | H26: 45444.167 | I26: 9.0658742 | J26: 11.117909 | K26: 0 | L26: 93.636678 | N26: 0 | O26: 0.0058002098 | P26: =+J26/SUM($J26:$O26) -> 0.10612703 | Q26: =+K26/SUM($J26:$O26) -> 0 | R26: =+L26/SUM($J26:$O26) -> 0.8938176 | S26: =+N26/SUM($J26:$O26) -> 0 | T26: =+P26*C26/1000/60/24.3*2*96485/-1/G26 -> 0.8874184 | U26: =+Q26*C26/1000/60/24.3*2*96485/-1/G26 -> 0 | W26: =T26+U26 -> 0.8874184 | X26: 0 | Y26: 93.6367
A27: Ag60 GDE in PTFE holder | B27: 60 | C27: =+'Flow rate'!E26 -> 69.176687 | D27: 0.3 M K2SO4 | E27: 0.05 M H2SO4 | F27: CCM-CEM | G27: -1.1 | H27: 45444.19 | I27: 9.6161519 | J27: 11.154408 | K27: 0 | L27: 93.676851 | N27: 0 | O27: 0.0063052089 | P27: =+J27/SUM($J27:$O27) -> 0.10639705 | Q27: =+K27/SUM($J27:$O27) -> 0 | R27: =+L27/SUM($J27:$O27) -> 0.89354281 | S27: =+N27/SUM($J27:$O27) -> 0 | T27: =+P27*C27/1000/60/24.3*2*96485/-1/G27 -> 0.88558232 | U27: =+Q27*C27/1000/60/24.3*2*96485/-1/G27 -> 0 | W27: =T27+U27 -> 0.88558232 | X27: 0
A28: Ag60 GDE in PTFE holder | B28: 60 | C28: =+'Flow rate'!E27 -> 69.49543 | D28: 0.3 M K2SO4 | E28: 0.05 M H2SO4 | F28: CCM-CEM | G28: -1.1 | H28: 45444.2 | I28: 9.8661519 | J28: 11.153991 | K28: 0 | L28: 93.389435 | N28: 0 | O28: 0 | P28: =+J28/SUM($J28:$O28) -> 0.10669242 | Q28: =+K28/SUM($J28:$O28) -> 0 | R28: =+L28/SUM($J28:$O28) -> 0.89330758 | S28: =+N28/SUM($J28:$O28) -> 0 | T28: =+P28*C28/1000/60/24.3*2*96485/-1/G28 -> 0.8921326 | U28: =+Q28*C28/1000/60/24.3*2*96485/-1/G28 -> 0 | W28: =T28+U28 -> 0.8921326 | X28: 0 | Y28: 93.3894
A29: Ag60 GDE in PTFE holder | B29: 60 | C29: =+'Flow rate'!E28 -> 75.031048 | D29: 0.3 M K2SO4 | E29: 0.05 M H2SO4 | F29: CCM-CEM | G29: -1.52 | H29: 45444.211 | I29: 10.11643 | J29: 13.507475 | K29: 0 | L29: 90.648686 | N29: 0.020798507 | O29: 0 | P29: =+J29/SUM($J29:$O29) -> 0.12965895 | Q29: =+K29/SUM($J29:$O29) -> 0 | R29: =+L29/SUM($J29:$O29) -> 0.8701414 | S29: =+N29/SUM($J29:$O29) -> 0.00019964594 | T29: =+P29*C29/1000/60/24.3*2*96485/-1/G29 -> 0.84709516 | U29: =+Q29*C29/1000/60/24.3*2*96485/-1/G29 -> 0 | W29: =T29+U29 -> 0.84709516 | X29: 0
A30: Ag60 GDE in PTFE holder | B30: 60 | C30: =+'Flow rate'!E29 -> 74.082651 | D30: 0.3 M K2SO4 | E30: 0.05 M H2SO4 | F30: CCM-CEM | G30: -1.52 | H30: 45444.221 | I30: 10.366707 | J30: 15.470259 | K30: 0 | L30: 88.294409 | N30: 0.035609134 | O30: 0 | P30: =+J30/SUM($J30:$O30) -> 0.14903871 | Q30: =+K30/SUM($J30:$O30) -> 0 | R30: =+L30/SUM($J30:$O30) -> 0.85061824 | S30: =+N30/SUM($J30:$O30) -> 0.00034305432 | T30: =+P30*C30/1000/60/24.3*2*96485/-1/G30 -> 0.96140035 | U30: =+Q30*C30/1000/60/24.3*2*96485/-1/G30 -> 0 | W30: =T30+U30 -> 0.96140035 | X30: 0 | Y30: 88.2944
A31: Ag60 GDE in PTFE holder | B31: 60 | C31: =+'Flow rate'!E30 -> 74.129111 | D31: 0.3 M K2SO4 | E31: 0.05 M H2SO4 | F31: CCM-CEM | G31: -1.52 | H31: 45444.232 | I31: 10.616985 | J31: 15.637952 | K31: 0 | L31: 88.100821 | N31: 0.034692245 | O31: 0 | P31: =+J31/SUM($J31:$O31) -> 0.15069316 | Q31: =+K31/SUM($J31:$O31) -> 0 | R31: =+L31/SUM($J31:$O31) -> 0.84897253 | S31: =+N31/SUM($J31:$O31) -> 0.00033430747 | T31: =+P31*C31/1000/60/24.3*2*96485/-1/G31 -> 0.97268234 | U31: =+Q31*C31/1000/60/24.3*2*96485/-1/G31 -> 0 | W31: =T31+U31 -> 0.97268234 | X31: 0
A32: Ag60 GDE in PTFE holder | B32: 60 | C32: =+'Flow rate'!E31 -> 73.810473 | D32: 0.3 M K2SO4 | E32: 0.05 M H2SO4 | F32: CCM-CEM | G32: -1.52 | H32: 45444.242 | I32: 10.867263 | J32: 15.687298 | K32: 0 | L32: 88.012185 | N32: 0.037026446 | O32: 0 | P32: =+J32/SUM($J32:$O32) -> 0.15122254 | Q32: =+K32/SUM($J32:$O32) -> 0 | R32: =+L32/SUM($J32:$O32) -> 0.84842053 | S32: =+N32/SUM($J32:$O32) -> 0.00035692782 | T32: =+P32*C32/1000/60/24.3*2*96485/-1/G32 -> 0.97190362 | U32: =+Q32*C32/1000/60/24.3*2*96485/-1/G32 -> 0 | W32: =T32+U32 -> 0.97190362 | X32: 0 | Y32: 88.0122
A33: Ag60 GDE in PTFE holder | B33: 60 | C33: =+'Flow rate'!E32 -> 73.614521 | D33: 0.3 M K2SO4 | E33: 0.05 M H2SO4 | F33: CCM-CEM | G33: -1.52 | H33: 45444.253 | I33: 11.117263 | J33: 15.729404 | K33: 0 | L33: 87.978482 | N33: 0.034619197 | O33: 0 | P33: =+J33/SUM($J33:$O33) -> 0.15161967 | Q33: =+K33/SUM($J33:$O33) -> 0 | R33: =+L33/SUM($J33:$O33) -> 0.84804663 | S33: =+N33/SUM($J33:$O33) -> 0.00033370312 | T33: =+P33*C33/1000/60/24.3*2*96485/-1/G33 -> 0.97186898 | U33: =+Q33*C33/1000/60/24.3*2*96485/-1/G33 -> 0 | W33: =T33+U33 -> 0.97186898 | X33: 0
A34: Ag60 GDE in PTFE holder | B34: 60 | C34: =+'Flow rate'!E33 -> 73.499422 | D34: 0.3 M K2SO4 | E34: 0.05 M H2SO4 | F34: CCM-CEM | G34: -1.52 | H34: 45444.263 | I34: 11.367819 | J34: 15.747012 | K34: 0 | L34: 87.921524 | N34: 0.03049628 | O34: 0 | P34: =+J34/SUM($J34:$O34) -> 0.15185303 | Q34: =+K34/SUM($J34:$O34) -> 0 | R34: =+L34/SUM($J34:$O34) -> 0.84785289 | S34: =+N34/SUM($J34:$O34) -> 0.00029408452 | T34: =+P34*C34/1000/60/24.3*2*96485/-1/G34 -> 0.97184289 | U34: =+Q34*C34/1000/60/24.3*2*96485/-1/G34 -> 0 | W34: =T34+U34 -> 0.97184289 | X34: 0 | Y34: 87.9215
A35: Ag60 GDE in PTFE holder | B35: 60 | C35: =+'Flow rate'!E34 -> 73.294742 | D35: 0.3 M K2SO4 | E35: 0.05 M H2SO4 | F35: CCM-CEM | G35: -1.52 | H35: 45444.281 | I35: 11.793096 | J35: 15.784557 | K35: 0 | L35: 88.098645 | N35: 0.034100275 | O35: 0.0046958674 | P35: =+J35/SUM($J35:$O35) -> 0.15188851 | Q35: =+K35/SUM($J35:$O35) -> 0 | R35: =+L35/SUM($J35:$O35) -> 0.84773817 | S35: =+N35/SUM($J35:$O35) -> 0.00032813337 | T35: =+P35*C35/1000/60/24.3*2*96485/-1/G35 -> 0.96936296 | U35: =+Q35*C35/1000/60/24.3*2*96485/-1/G35 -> 0 | W35: =T35+U35 -> 0.96936296 | X35: 0
A36: Ag60 GDE in PTFE holder | B36: 60 | C36: =+'Flow rate'!E35 -> 78.912152 | D36: 0.3 M K2SO4 | E36: 0.05 M H2SO4 | F36: CCM-CEM | G36: -2.1 | H36: 45444.291 | I36: 12.043374 | J36: 16.22437 | K36: 0.0054466058 | L36: 87.263462 | N36: 0.039871743 | O36: 0 | P36: =+J36/SUM($J36:$O36) -> 0.15670701 | Q36: =+K36/SUM($J36:$O36) -> 5.2607361e-05 | R36: =+L36/SUM($J36:$O36) -> 0.84285527 | S36: =+N36/SUM($J36:$O36) -> 0.00038511088 | T36: =+P36*C36/1000/60/24.3*2*96485/-1/G36 -> 0.77937288 | U36: =+Q36*C36/1000/60/24.3*2*96485/-1/G36 -> 0.00026163954 | W36: =T36+U36 -> 0.77963452 | X36: 6.1877714e-05 | Y36: 87.2689
A37: Ag60 GDE in PTFE holder | B37: 60 | C37: =+'Flow rate'!E36 -> 78.759952 | D37: 0.3 M K2SO4 | E37: 0.05 M H2SO4 | F37: CCM-CEM | G37: -2.1 | H37: 45444.301 | I37: 12.293096 | J37: 19.60135 | K37: 0.053780809 | L37: 83.132854 | N37: 0.15340708 | O37: 0 | P37: =+J37/SUM($J37:$O37) -> 0.19041272 | Q37: =+K37/SUM($J37:$O37) -> 0.00052244105 | R37: =+L37/SUM($J37:$O37) -> 0.8075746 | S37: =+N37/SUM($J37:$O37) -> 0.0014902371 | T37: =+P37*C37/1000/60/24.3*2*96485/-1/G37 -> 0.94517967 | U37: =+Q37*C37/1000/60/24.3*2*96485/-1/G37 -> 0.0025933177 | W37: =T37+U37 -> 0.94777299 | X37: 0.000646738
A38: Ag60 GDE in PTFE holder | B38: 60 | C38: =+'Flow rate'!E37 -> 78.212569 | D38: 0.3 M K2SO4 | E38: 0.05 M H2SO4 | F38: CCM-CEM | G38: -2.1 | H38: 45444.312 | I38: 12.543374 | J38: 19.834841 | K38: 0.051233245 | L38: 82.901577 | N38: 0.13656606 | O38: 0 | P38: =+J38/SUM($J38:$O38) -> 0.19271306 | Q38: =+K38/SUM($J38:$O38) -> 0.00049777639 | R38: =+L38/SUM($J38:$O38) -> 0.8054623 | S38: =+N38/SUM($J38:$O38) -> 0.0013268603 | T38: =+P38*C38/1000/60/24.3*2*96485/-1/G38 -> 0.94994986 | U38: =+Q38*C38/1000/60/24.3*2*96485/-1/G38 -> 0.0024537133 | W38: =T38+U38 -> 0.95240357 | X38: 0.00061721847 | Y38: 82.9528
A39: Ag60 GDE in PTFE holder | B39: 60 | C39: =+'Flow rate'!E38 -> 77.973544 | D39: 0.3 M K2SO4 | E39: 0.05 M H2SO4 | F39: CCM-CEM | G39: -2.1 | H39: 45444.322 | I39: 12.79393 | J39: 19.902984 | K39: 0.046766403 | L39: 82.775256 | N39: 0.13658812 | O39: 0 | P39: =+J39/SUM($J39:$O39) -> 0.19349286 | Q39: =+K39/SUM($J39:$O39) -> 0.00045465369 | R39: =+L39/SUM($J39:$O39) -> 0.80472461 | S39: =+N39/SUM($J39:$O39) -> 0.0013278826 | T39: =+P39*C39/1000/60/24.3*2*96485/-1/G39 -> 0.95087885 | U39: =+Q39*C39/1000/60/24.3*2*96485/-1/G39 -> 0.0022342973 | W39: =T39+U39 -> 0.95311315 | X39: 0.00056506657
A40: Ag60 GDE in PTFE holder | B40: 60 | C40: =+'Flow rate'!E39 -> 77.860641 | D40: 0.3 M K2SO4 | E40: 0.05 M H2SO4 | F40: CCM-CEM | G40: -2.1 | H40: 45444.333 | I40: 13.044207 | J40: 19.949736 | K40: 0.04720261 | L40: 82.735015 | N40: 0.13454006 | O40: 0 | P40: =+J40/SUM($J40:$O40) -> 0.19393813 | Q40: =+K40/SUM($J40:$O40) -> 0.00045887254 | R40: =+L40/SUM($J40:$O40) -> 0.80429508 | S40: =+N40/SUM($J40:$O40) -> 0.0013079094 | T40: =+P40*C40/1000/60/24.3*2*96485/-1/G40 -> 0.95168707 | U40: =+Q40*C40/1000/60/24.3*2*96485/-1/G40 -> 0.0022517648 | W40: =T40+U40 -> 0.95393883 | X40: 0.00057017088 | Y40: 82.7822
...

Sheet Flow rate
B1: 0.6Mk2so4pH1 | C1: =+Sheet1!H2 -> 45443.789 | D1: =+C1-2/24 -> 45443.706 | E1: {=INDEX(B$1:B$224233, MATCH(D1,A$1:A$224233,1) +0)} -> 58.815907
A2: 45443.61 | B2: 0 | C2: =+Sheet1!H3 -> 45443.793 | D2: =+C2-2/24 -> 45443.71 | E2: {=INDEX(B$1:B$224233, MATCH(D2,A$1:A$224233,1) +0)} -> 60.413028
A3: 45443.61 | B3: 26.609639 | C3: =+Sheet1!H4 -> 45443.808 | D3: =+C3-2/24 -> 45443.725 | E3: {=INDEX(B$1:B$224233, MATCH(D3,A$1:A$224233,1) +0)} -> 61.367047
A4: 45443.611 | B4: 44.966346 | C4: =+Sheet1!H5 -> 45443.824 | D4: =+C4-2/24 -> 45443.741 | E4: {=INDEX(B$1:B$224233, MATCH(D4,A$1:A$224233,1) +0)} -> 61.254046
A5: 45443.612 | B5: 30.416798 | C5: =+Sheet1!H6 -> 45443.84 | D5: =+C5-2/24 -> 45443.756 | E5: {=INDEX(B$1:B$224233, MATCH(D5,A$1:A$224233,1) +0)} -> 61.057261
A6: 45443.613 | B6: 37.172205 | C6: =+Sheet1!H7 -> 45443.855 | D6: =+C6-2/24 -> 45443.772 | E6: {=INDEX(B$1:B$224233, MATCH(D6,A$1:A$224233,1) +0)} -> 61.700919
A7: 45443.613 | B7: 45.621314 | C7: =+Sheet1!H8 -> 45443.871 | D7: =+C7-2/24 -> 45443.788 | E7: {=INDEX(B$1:B$224233, MATCH(D7,A$1:A$224233,1) +0)} -> 61.782924
A8: 45443.614 | B8: 45.698639 | C8: =+Sheet1!H9 -> 45443.887 | D8: =+C8-2/24 -> 45443.803 | E8: {=INDEX(B$1:B$224233, MATCH(D8,A$1:A$224233,1) +0)} -> 63.533286
A9: 45443.615 | B9: 45.845561 | C9: =+Sheet1!H10 -> 45443.902 | D9: =+C9-2/24 -> 45443.819 | E9: {=INDEX(B$1:B$224233, MATCH(D9,A$1:A$224233,1) +0)} -> 63.664311
A10: 45443.615 | B10: 46.211433 | C10: =+Sheet1!H11 -> 45443.925 | D10: =+C10-2/24 -> 45443.842 | E10: {=INDEX(B$1:B$224233, MATCH(D10,A$1:A$224233,1) +0)} -> 63.458614
A11: 45443.616 | B11: 46.171077 | C11: =+Sheet1!H12 -> 45443.941 | D11: =+C11-2/24 -> 45443.858 | E11: {=INDEX(B$1:B$224233, MATCH(D11,A$1:A$224233,1) +0)} -> 63.347826
A12: 45443.617 | B12: 45.696554 | C12: =+Sheet1!H13 -> 45443.956 | D12: =+C12-2/24 -> 45443.873 | E12: {=INDEX(B$1:B$224233, MATCH(D12,A$1:A$224233,1) +0)} -> 64.646482
A13: 45443.617 | B13: 45.774403 | C13: =+Sheet1!H14 -> 45443.972 | D13: =+C13-2/24 -> 45443.889 | E13: {=INDEX(B$1:B$224233, MATCH(D13,A$1:A$224233,1) +0)} -> 65.777474
... A62: 45443.651 | B62: 54.232367 | C62: =+Sheet1!H63 -> 45444.594 | D62: =+C62-2/24 -> 45444.511 | E62: {=INDEX(B$1:B$224233, MATCH(D62,A$1:A$224233,1) +0)} -> 55.956791
A63: 45443.652 | B63: 54.306147
A64: 45443.653 | B64: 54.719558
A65: 45443.653 | B65: 54.574307
A66: 45443.654 | B66: 55.031739
A67: 45443.655 | B67: 54.975041
A68: 45443.656 | B68: 54.697668
A69: 45443.656 | B69: 55.108794
A70: 45443.657 | B70: 55.379369
A71: 45443.658 | B71: 55.453665
A72: 45443.658 | B72: 54.558613
A73: 45443.659 | B73: 55.3911
A74: 45443.66 | B74: 55.389822
... A1454: 45444.618 | B1454: 52.980944
