Workbook

Sheet Acidic Catholyte_Na2SO4
A1: Electrode | B1: Inlet flow rate | C1: Flow rate (ml min-1) | D1: Catholyte | E1: Anolyte | F1: Membrane | G1: Applied current / A | H1: Time | I1: Duration / h | J1: area(H2) | K1: area(CO) | L1: area(CO2) | M1: area(CH4) | N1: area(O2) | O1: area(N2) | P1: c(H2) | Q1: c(CO) | R1: c(CO2) | S1: c(O2) | T1: FE(H2) | U1: FE(CO) | V1: FE(CH4) | W1: Total FE | X1: Carbon efficiency
A2: Ag60 GDE in PTFE holder | B2: 60 | C2: =+'Flow rate'!E1 -> 51.4 | D2: 0.3 M Na2SO4 | E2: 0.05 M H2SO4 | F2: CCM-CEM | G2: -0.107 | H2: 45412.484 | I2: 0 | J2: 0 | K2: 0 | L2: 0 | P2: =+J2/100 -> 0 | Q2: =+K2/100 -> 0 | R2: =+L2/100 -> 0 | S2: =+N2/100 -> 0 | T2: 0 | U2: 0 | W2: 0 | X2: 0
A3: Ag60 GDE in PTFE holder | B3: 60 | C3: =+'Flow rate'!E2 -> 54.1 | D3: 0.3 M Na2SO4 | E3: 0.05 M H2SO4 | F3: CCM-CEM | G3: -0.107 | H3: 45412.497 | I3: =+(H3-H$2)*24 -> 0.3 | J3: 1.463835 | K3: 0.13249176 | L3: 100.73552 | N3: 0.18274548 | O3: 0.41898139 | P3: =+J3/SUM($J3:$O3) -> 0.014221162 | Q3: =+K3/SUM($J3:$O3) -> 0.0012871579 | R3: =+L3/SUM($J3:$O3) -> 0.9786459 | S3: =+N3/SUM($J3:$O3) -> 0.0017753729 | T3: =+P3*C3/1000/60/24.3*2*96485/-1/G3 -> 0.95165787 | U3: =+Q3*C3/1000/60/24.3*2*96485/-1/G3 -> 0.086134587 | W3: =+T3+U3 -> 1.0377925 | X3: =+K3/(K3+L3) -> 0.0013135161
A4: Ag60 GDE in PTFE holder | B4: 60 | C4: =+'Flow rate'!E3 -> 56.4 | D4: 0.3 M Na2SO4 | E4: 0.05 M H2SO4 | F4: CCM-CEM | G4: -0.107 | H4: 45412.52 | I4: =+(H4-H$2)*24 -> 0.86666667 | J4: 1.5029162 | K4: 0.24351219 | L4: 100.87689 | N4: 0.11542301 | O4: 0.0020328663 | P4: =+J4/SUM($J4:$O4) -> 0.014628234 | Q4: =+K4/SUM($J4:$O4) -> 0.002370161 | R4: =+L4/SUM($J4:$O4) -> 0.98185838 | S4: =+N4/SUM($J4:$O4) -> 0.0011234391 | T4: =+P4*C4/1000/60/24.3*2*96485/-1/G4 -> 1.0205153 | U4: =+Q4*C4/1000/60/24.3*2*96485/-1/G4 -> 0.16535048 | W4: =+T4+U4 -> 1.1858658 | X4: =+K4/(K4+L4) -> 0.0024081409 | Y4: =+SUM(K4:L4) -> 101.12041
A5: Ag60 GDE in PTFE holder | B5: 60 | C5: =+'Flow rate'!E4 -> 58.2 | D5: 0.3 M Na2SO4 | E5: 0.05 M H2SO4 | F5: CCM-CEM | G5: -0.107 | H5: 45412.556 | I5: =+(H5-H$2)*24 -> 1.7333333 | J5: 1.3065707 | K5: 0.38515702 | L5: 100.99946 | N5: 0.08051441 | O5: 0.0016609532 | P5: =+J5/SUM($J5:$O5) -> 0.012713126 | Q5: =+K5/SUM($J5:$O5) -> 0.0037476347 | R5: =+L5/SUM($J5:$O5) -> 0.98273966 | S5: =+N5/SUM($J5:$O5) -> 0.00078341711 | T5: =+P5*C5/1000/60/24.3*2*96485/-1/G5 -> 0.91521649 | U5: =+Q5*C5/1000/60/24.3*2*96485/-1/G5 -> 0.26979179 | W5: =+T5+U5 -> 1.1850083 | X5: =+K5/(K5+L5) -> 0.0037989691
A6: Ag60 GDE in PTFE holder | B6: 60 | C6: =+'Flow rate'!E5 -> 58.7 | D6: 0.3 M Na2SO4 | E6: 0.05 M H2SO4 | F6: CCM-CEM | G6: -0.25 | H6: 45412.598 | I6: =+(H6-H$2)*24 -> 2.7333333 | J6: 0.66959518 | K6: 2.935072 | L6: 99.133421 | N6: 0.059833497 | O6: 0.0019212214 | P6: =+J6/SUM($J6:$O6) -> 0.0065135818 | Q6: =+K6/SUM($J6:$O6) -> 0.028551327 | R6: =+L6/SUM($J6:$O6) -> 0.96433436 | S6: =+N6/SUM($J6:$O6) -> 0.00058203879 | T6: =+P6*C6/1000/60/24.3*2*96485/-1/G6 -> 0.20241852 | U6: =+Q6*C6/1000/60/24.3*2*96485/-1/G6 -> 0.88727178 | W6: =+T6+U6 -> 1.0896903 | X6: =+K6/(K6+L6) -> 0.028755906 | Y6: =+SUM(K6:L6) -> 102.06849
A7: Ag60 GDE in PTFE holder | B7: 60 | C7: =+'Flow rate'!E6 -> 59.5 | D7: 0.3 M Na2SO4 | E7: 0.05 M H2SO4 | F7: CCM-CEM | G7: -0.25 | H7: 45412.64 | I7: =+(H7-H$2)*24 -> 3.75 | J7: 0.78932616 | K7: 2.7953559 | L7: 99.00726 | N7: 0.051699679 | O7: 0.0021336787 | P7: =+J7/SUM($J7:$O7) -> 0.0076898066 | Q7: =+K7/SUM($J7:$O7) -> 0.027233034 | R7: =+L7/SUM($J7:$O7) -> 0.9645527 | S7: =+N7/SUM($J7:$O7) -> 0.00050367079 | T7: =+P7*C7/1000/60/24.3*2*96485/-1/G7 -> 0.24222817 | U7: =+Q7*C7/1000/60/24.3*2*96485/-1/G7 -> 0.85783795 | W7: =+T7+U7 -> 1.1000661 | X7: =+K7/(K7+L7) -> 0.027458586
A8: Ag60 GDE in PTFE holder | B8: 60 | C8: =+'Flow rate'!E7 -> 59.3 | D8: 0.3 M Na2SO4 | E8: 0.05 M H2SO4 | F8: CCM-CEM | G8: -0.52 | H8: 45412.664 | I8: =+(H8-H$2)*24 -> 4.3166667 | J8: 0.68906852 | K8: 5.4731078 | L8: 96.947091 | N8: 0.050708369 | O8: 0.0016239342 | P8: =+J8/SUM($J8:$O8) -> 0.006679506 | Q8: =+K8/SUM($J8:$O8) -> 0.053053731 | R8: =+L8/SUM($J8:$O8) -> 0.93975948 | S8: =+N8/SUM($J8:$O8) -> 0.00049154307 | T8: =+P8*C8/1000/60/24.3*2*96485/-1/G8 -> 0.10081565 | U8: =+Q8*C8/1000/60/24.3*2*96485/-1/G8 -> 0.80075481 | W8: =+T8+U8 -> 0.90157046 | X8: =+K8/(K8+L8) -> 0.053437777 | Y8: =+SUM(K8:L8) -> 102.4202
A9: Ag60 GDE in PTFE holder | B9: 60 | C9: =+'Flow rate'!E8 -> 59.1 | D9: 0.3 M Na2SO4 | E9: 0.05 M H2SO4 | F9: CCM-CEM | G9: -0.52 | H9: 45412.688 | I9: =+(H9-H$2)*24 -> 4.8833333 | J9: 0.74276785 | K9: 5.6996067 | L9: 96.653978 | N9: 0.04967915 | O9: 0.0015866903 | P9: =+J9/SUM($J9:$O9) -> 0.007201018 | Q9: =+K9/SUM($J9:$O9) -> 0.055256794 | R9: =+L9/SUM($J9:$O9) -> 0.93704517 | S9: =+N9/SUM($J9:$O9) -> 0.00048163158 | T9: =+P9*C9/1000/60/24.3*2*96485/-1/G9 -> 0.10832041 | U9: =+Q9*C9/1000/60/24.3*2*96485/-1/G9 -> 0.83119341 | W9: =+T9+U9 -> 0.93951383 | X9: =+K9/(K9+L9) -> 0.055685462
A10: Ag60 GDE in PTFE holder | B10: 60 | C10: =+'Flow rate'!E9 -> 58.8 | D10: 0.3 M Na2SO4 | E10: 0.05 M H2SO4 | F10: CCM-CEM | G10: -0.52 | H10: 45412.712 | I10: =+(H10-H$2)*24 -> 5.4666667 | J10: 0.77996722 | K10: 5.6558228 | L10: 96.573859 | N10: 0.049579609 | O10: 0.0017831439 | P10: =+J10/SUM($J10:$O10) -> 0.0075680144 | Q10: =+K10/SUM($J10:$O10) -> 0.054878394 | R10: =+L10/SUM($J10:$O10) -> 0.93705522 | S10: =+N10/SUM($J10:$O10) -> 0.00048107046 | T10: =+P10*C10/1000/60/24.3*2*96485/-1/G10 -> 0.11326304 | U10: =+Q10*C10/1000/60/24.3*2*96485/-1/G10 -> 0.82131101 | W10: =+T10+U10 -> 0.93457405 | X10: =+K10/(K10+L10) -> 0.055324664 | Y10: =+SUM(K10:L10) -> 102.22968
A11: Ag60 GDE in PTFE holder | B11: 60 | C11: =+'Flow rate'!E10 -> 59.3 | D11: 0.3 M Na2SO4 | E11: 0.05 M H2SO4 | F11: CCM-CEM | G11: -0.76 | H11: 45412.748 | I11: =+(H11-H$2)*24 -> 6.3333333 | J11: 1.4276037 | K11: 7.558075 | L11: 94.284345 | N11: 0.047759776 | O11: 0.0075558353 | P11: =+J11/SUM($J11:$O11) -> 0.013816588 | Q11: =+K11/SUM($J11:$O11) -> 0.07314832 | R11: =+L11/SUM($J11:$O11) -> 0.91249974 | S11: =+N11/SUM($J11:$O11) -> 0.00046222714 | T11: =+P11*C11/1000/60/24.3*2*96485/-1/G11 -> 0.14268364 | U11: =+Q11*C11/1000/60/24.3*2*96485/-1/G11 -> 0.7554013 | W11: =+T11+U11 -> 0.89808494 | X11: =+K11/(K11+L11) -> 0.074213427
A12: Ag60 GDE in PTFE holder | B12: 60 | C12: =+'Flow rate'!E11 -> 59.6 | D12: 0.3 M Na2SO4 | E12: 0.05 M H2SO4 | F12: CCM-CEM | G12: -0.76 | H12: 45412.784 | I12: =+(H12-H$2)*24 -> 7.2 | J12: 1.7763367 | K12: 7.2003554 | L12: 93.12462 | N12: 0.049107445 | O12: 0.0015969927 | P12: =+J12/SUM($J12:$O12) -> 0.017389149 | Q12: =+K12/SUM($J12:$O12) -> 0.07048667 | R12: =+L12/SUM($J12:$O12) -> 0.91162782 | S12: =+N12/SUM($J12:$O12) -> 0.00048072908 | T12: =+P12*C12/1000/60/24.3*2*96485/-1/G12 -> 0.1804859 | U12: =+Q12*C12/1000/60/24.3*2*96485/-1/G12 -> 0.73159703 | W12: =+T12+U12 -> 0.91208293 | X12: =+K12/(K12+L12) -> 0.071770319 | Y12: =+SUM(K12:L12) -> 100.32498
A13: Ag60 GDE in PTFE holder | B13: 60 | C13: =+'Flow rate'!E12 -> 60.1 | D13: 0.3 M Na2SO4 | E13: 0.05 M H2SO4 | F13: CCM-CEM | G13: -1.1 | H13: 45412.82 | I13: =+(H13-H$2)*24 -> 8.0666667 | J13: 1.9805121 | K13: 7.2279469 | L13: 93.404633 | N13: 0.047472912 | O13: 0.0016647146 | P13: =+J13/SUM($J13:$O13) -> 0.019291536 | Q13: =+K13/SUM($J13:$O13) -> 0.070405124 | R13: =+L13/SUM($J13:$O13) -> 0.90982471 | S13: =+N13/SUM($J13:$O13) -> 0.00046241848 | T13: =+P13*C13/1000/60/24.3*2*96485/-1/G13 -> 0.13950214 | U13: =+Q13*C13/1000/60/24.3*2*96485/-1/G13 -> 0.50911785 | W13: =+T13+U13 -> 0.64861999 | X13: =+K13/(K13+L13) -> 0.071825118
A14: Ag60 GDE in PTFE holder | B14: 60 | C14: =+'Flow rate'!E13 -> 60.1 | D14: 0.3 M Na2SO4 | E14: 0.05 M H2SO4 | F14: CCM-CEM | G14: -1.1 | H14: 45412.844 | I14: =+(H14-H$2)*24 -> 8.6333333 | J14: 2.8631016 | K14: 8.4990976 | L14: 91.228941 | N14: 0.049279111 | O14: 0.0013292039 | P14: =+J14/SUM($J14:$O14) -> 0.027894124 | Q14: =+K14/SUM($J14:$O14) -> 0.082803515 | R14: =+L14/SUM($J14:$O14) -> 0.8888093 | S14: =+N14/SUM($J14:$O14) -> 0.00048010786 | T14: =+P14*C14/1000/60/24.3*2*96485/-1/G14 -> 0.2017097 | U14: =+Q14*C14/1000/60/24.3*2*96485/-1/G14 -> 0.59877386 | W14: =+T14+U14 -> 0.80048356 | X14: =+K14/(K14+L14) -> 0.085222749 | Y14: =+SUM(K14:L14) -> 99.728039
A15: Ag60 GDE in PTFE holder | B15: 60 | C15: =+'Flow rate'!E14 -> 60 | D15: 0.3 M Na2SO4 | E15: 0.05 M H2SO4 | F15: CCM-CEM | G15: -1.1 | H15: 45412.861 | I15: =+(H15-H$2)*24 -> 9.05 | J15: 2.9218101 | K15: 8.4724243 | L15: 91.268317 | N15: 0.048643687 | O15: 0.0012287746 | P15: =+J15/SUM($J15:$O15) -> 0.028446511 | Q15: =+K15/SUM($J15:$O15) -> 0.082486849 | R15: =+L15/SUM($J15:$O15) -> 0.88858109 | S15: =+N15/SUM($J15:$O15) -> 0.00047359107 | T15: =+P15*C15/1000/60/24.3*2*96485/-1/G15 -> 0.20536189 | U15: =+Q15*C15/1000/60/24.3*2*96485/-1/G15 -> 0.59549148 | W15: =+T15+U15 -> 0.80085337 | X15: =+K15/(K15+L15) -> 0.084944468
A16: Ag60 GDE in PTFE holder | B16: 60 | C16: =+'Flow rate'!E15 -> 60.1 | D16: 0.3 M Na2SO4 | E16: 0.05 M H2SO4 | F16: CCM-CEM | G16: -1.1 | H16: 45412.879 | I16: =+(H16-H$2)*24 -> 9.4833333 | J16: 2.9826454 | K16: 8.4328759 | L16: 91.165468 | N16: 0.049578841 | O16: 0.001648363 | P16: =+J16/SUM($J16:$O16) -> 0.029061492 | Q16: =+K16/SUM($J16:$O16) -> 0.082165972 | R16: =+L16/SUM($J16:$O16) -> 0.8882734 | S16: =+N16/SUM($J16:$O16) -> 0.00048307288 | T16: =+P16*C16/1000/60/24.3*2*96485/-1/G16 -> 0.21015125 | U16: =+Q16*C16/1000/60/24.3*2*96485/-1/G16 -> 0.59416362 | W16: =+T16+U16 -> 0.80431487 | X16: =+K16/(K16+L16) -> 0.084668836 | Y16: =+SUM(K16:L16) -> 99.598344
A17: Ag60 GDE in PTFE holder | B17: 60 | C17: =+'Flow rate'!E16 -> 59.8 | D17: 0.3 M Na2SO4 | E17: 0.05 M H2SO4 | F17: CCM-CEM | G17: -1.1 | H17: 45412.897 | I17: =+(H17-H$2)*24 -> 9.9 | J17: 3.0491527 | K17: 8.3290103 | L17: 91.144446 | N17: 0.048706979 | O17: 0.0014200486 | P17: =+J17/SUM($J17:$O17) -> 0.029726737 | Q17: =+K17/SUM($J17:$O17) -> 0.081201015 | R17: =+L17/SUM($J17:$O17) -> 0.88858355 | S17: =+N17/SUM($J17:$O17) -> 0.00047485307 | T17: =+P17*C17/1000/60/24.3*2*96485/-1/G17 -> 0.21388878 | U17: =+Q17*C17/1000/60/24.3*2*96485/-1/G17 -> 0.58425472 | W17: =+T17+U17 -> 0.7981435 | X17: =+K17/(K17+L17) -> 0.083730983
A18: Ag60 GDE in PTFE holder | B18: 60 | C18: =+'Flow rate'!E17 -> 63.5 | D18: 0.3 M Na2SO4 | E18: 0.05 M H2SO4 | F18: CCM-CEM | G18: -1.52 | H18: 45412.915 | I18: =+(H18-H$2)*24 -> 10.333333 | J18: 6.5798087 | K18: 9.000521 | L18: 87.175385 | N18: 0.050514351 | O18: 0.0015452262 | P18: =+J18/SUM($J18:$O18) -> 0.064001082 | Q18: =+K18/SUM($J18:$O18) -> 0.087547085 | R18: =+L18/SUM($J18:$O18) -> 0.84794546 | S18: =+N18/SUM($J18:$O18) -> 0.00049134758 | T18: =+P18*C18/1000/60/24.3*2*96485/-1/G18 -> 0.35387487 | U18: =+Q18*C18/1000/60/24.3*2*96485/-1/G18 -> 0.48406547 | W18: =+T18+U18 -> 0.83794034 | X18: =+K18/(K18+L18) -> 0.093583948 | Y18: =+SUM(K18:L18) -> 96.175906
A19: Ag60 GDE in PTFE holder | B19: 60 | C19: =+'Flow rate'!E18 -> 63.3 | D19: 0.3 M Na2SO4 | E19: 0.05 M H2SO4 | F19: CCM-CEM | G19: -1.52 | H19: 45412.932 | I19: =+(H19-H$2)*24 -> 10.75 | J19: 7.2556478 | K19: 8.6877688 | L19: 86.676271 | N19: 0.050171333 | O19: 0.0013235874 | P19: =+J19/SUM($J19:$O19) -> 0.070668786 | Q19: =+K19/SUM($J19:$O19) -> 0.084617403 | R19: =+L19/SUM($J19:$O19) -> 0.84421226 | S19: =+N19/SUM($J19:$O19) -> 0.00048866032 | T19: =+P19*C19/1000/60/24.3*2*96485/-1/G19 -> 0.38951127 | U19: =+Q19*C19/1000/60/24.3*2*96485/-1/G19 -> 0.46639307 | W19: =+T19+U19 -> 0.85590433 | X19: =+K19/(K19+L19) -> 0.091101099
A20: Ag60 GDE in PTFE holder | B20: 60 | C20: =+'Flow rate'!E19 -> 63.4 | D20: 0.3 M Na2SO4 | E20: 0.05 M H2SO4 | F20: CCM-CEM | G20: -1.52 | H20: 45412.95 | I20: =+(H20-H$2)*24 -> 11.183333 | J20: 7.4883165 | K20: 8.5670262 | L20: 86.596063 | N20: 0.049586392 | O20: 0.0015068947 | P20: =+J20/SUM($J20:$O20) -> 0.072912699 | Q20: =+K20/SUM($J20:$O20) -> 0.083415947 | R20: =+L20/SUM($J20:$O20) -> 0.84317387 | S20: =+N20/SUM($J20:$O20) -> 0.00048281582 | T20: =+P20*C20/1000/60/24.3*2*96485/-1/G20 -> 0.40251412 | U20: =+Q20*C20/1000/60/24.3*2*96485/-1/G20 -> 0.46049724 | W20: =+T20+U20 -> 0.86301136 | X20: =+K20/(K20+L20) -> 0.090024675 | Y20: =+SUM(K20:L20) -> 95.163089
A21: Ag60 GDE in PTFE holder | B21: 60 | C21: =+'Flow rate'!E20 -> 63 | D21: 0.3 M Na2SO4 | E21: 0.05 M H2SO4 | F21: CCM-CEM | G21: -1.52 | H21: 45412.967 | I21: =+(H21-H$2)*24 -> 11.6 | J21: 7.6126597 | K21: 8.5323629 | L21: 86.557595 | N21: 0.049815675 | O21: 0.0015299358 | P21: =+J21/SUM($J21:$O21) -> 0.074086288 | Q21: =+K21/SUM($J21:$O21) -> 0.083036826 | R21: =+L21/SUM($J21:$O21) -> 0.84237719 | S21: =+N21/SUM($J21:$O21) -> 0.00048480539 | T21: =+P21*C21/1000/60/24.3*2*96485/-1/G21 -> 0.40641251 | U21: =+Q21*C21/1000/60/24.3*2*96485/-1/G21 -> 0.45551216 | W21: =+T21+U21 -> 0.86192467 | X21: =+K21/(K21+L21) -> 0.08972938
A22: Ag60 GDE in PTFE holder | B22: 60 | C22: =+'Flow rate'!E21 -> 66.9 | D22: 0.3 M Na2SO4 | E22: 0.05 M H2SO4 | F22: CCM-CEM | G22: -2.1 | H22: 45412.985 | I22: =+(H22-H$2)*24 -> 12.033333 | J22: 7.6570528 | K22: 8.6137543 | L22: 86.358581 | N22: 0.049753137 | O22: 0.001422406 | P22: =+J22/SUM($J22:$O22) -> 0.074571589 | Q22: =+K22/SUM($J22:$O22) -> 0.083888849 | R22: =+L22/SUM($J22:$O22) -> 0.84104117 | S22: =+N22/SUM($J22:$O22) -> 0.00048454289 | T22: =+P22*C22/1000/60/24.3*2*96485/-1/G22 -> 0.31442169 | U22: =+Q22*C22/1000/60/24.3*2*96485/-1/G22 -> 0.35370674 | W22: =+T22+U22 -> 0.66812843 | X22: =+K22/(K22+L22) -> 0.09069751 | Y22: =+SUM(K22:L22) -> 94.972335
A23: Ag60 GDE in PTFE holder | B23: 60 | C23: =+'Flow rate'!E22 -> 66.8 | D23: 0.3 M Na2SO4 | E23: 0.05 M H2SO4 | F23: CCM-CEM | G23: -2.1 | H23: 45413.003 | I23: =+(H23-H$2)*24 -> 12.45 | J23: 11.836662 | K23: 8.6327435 | L23: 82.375399 | N23: 0.051067999 | O23: 0.0014338771 | P23: =+J23/SUM($J23:$O23) -> 0.11503374 | Q23: =+K23/SUM($J23:$O23) -> 0.08389669 | R23: =+L23/SUM($J23:$O23) -> 0.80055933 | S23: =+N23/SUM($J23:$O23) -> 0.00049630064 | T23: =+P23*C23/1000/60/24.3*2*96485/-1/G23 -> 0.48430025 | U23: =+Q23*C23/1000/60/24.3*2*96485/-1/G23 -> 0.35321104 | W23: =+T23+U23 -> 0.83751129 | X23: =+K23/(K23+L23) -> 0.094856825
A24: Ag60 GDE in PTFE holder | B24: 60 | C24: =+'Flow rate'!E23 -> 67.1 | D24: 0.3 M Na2SO4 | E24: 0.05 M H2SO4 | F24: CCM-CEM | G24: -2.1 | H24: 45413.021 | I24: =+(H24-H$2)*24 -> 12.883333 | J24: 12.158981 | K24: 8.4915474 | L24: 82.219292 | N24: 0.05071032 | O24: 0.0015641454 | P24: =+J24/SUM($J24:$O24) -> 0.11813772 | Q24: =+K24/SUM($J24:$O24) -> 0.082504611 | R24: =+L24/SUM($J24:$O24) -> 0.79884977 | S24: =+N24/SUM($J24:$O24) -> 0.00049270586 | T24: =+P24*C24/1000/60/24.3*2*96485/-1/G24 -> 0.49960189 | U24: =+Q24*C24/1000/60/24.3*2*96485/-1/G24 -> 0.34891024 | W24: =+T24+U24 -> 0.84851213 | X24: =+K24/(K24+L24) -> 0.093611165 | Y24: =+SUM(K24:L24) -> 90.71084
A25: Ag60 GDE in PTFE holder | B25: 60 | C25: =+'Flow rate'!E24 -> 66.7 | D25: 0.3 M Na2SO4 | E25: 0.05 M H2SO4 | F25: CCM-CEM | G25: -2.1 | H25: 45413.044 | I25: =+(H25-H$2)*24 -> 13.45 | J25: 12.364514 | K25: 8.3790034 | L25: 82.010761 | N25: 0.05112505 | O25: 0.0014344492 | P25: =+J25/SUM($J25:$O25) -> 0.12026937 | Q25: =+K25/SUM($J25:$O25) -> 0.081502394 | R25: =+L25/SUM($J25:$O25) -> 0.79771699 | S25: =+N25/SUM($J25:$O25) -> 0.00049729231 | T25: =+P25*C25/1000/60/24.3*2*96485/-1/G25 -> 0.50558462 | U25: =+Q25*C25/1000/60/24.3*2*96485/-1/G25 -> 0.34261721 | W25: =+T25+U25 -> 0.84820183 | X25: =+K25/(K25+L25) -> 0.092698587
A26: Ag60 GDE in PTFE holder | B26: 60 | C26: =+'Flow rate'!E25 -> 67.1 | D26: 0.3 M Na2SO4 | E26: 0.05 M H2SO4 | F26: CCM-CEM | G26: -2.1 | H26: 45413.062 | I26: =+(H26-H$2)*24 -> 13.883333 | J26: 12.658993 | K26: 8.0728871 | L26: 82.081489 | N26: 0.051090266 | O26: 0.0012190075 | P26: =+J26/SUM($J26:$O26) -> 0.12306333 | Q26: =+K26/SUM($J26:$O26) -> 0.07847989 | R26: =+L26/SUM($J26:$O26) -> 0.79794826 | S26: =+N26/SUM($J26:$O26) -> 0.0004966697 | T26: =+P26*C26/1000/60/24.3*2*96485/-1/G26 -> 0.5204322 | U26: =+Q26*C26/1000/60/24.3*2*96485/-1/G26 -> 0.33188978 | W26: =+T26+U26 -> 0.85232198 | X26: =+K26/(K26+L26) -> 0.08954515 | Y26: =+SUM(K26:L26) -> 90.154376
A27: Ag60 GDE in PTFE holder | B27: 60 | C27: =+'Flow rate'!E26 -> 75.2 | D27: 0.3 M Na2SO4 | E27: 0.05 M H2SO4 | F27: CCM-CEM | G27: -3.1 | H27: 45413.08 | I27: =+(H27-H$2)*24 -> 14.3 | J27: 20.412791 | K27: 7.5704488 | L27: 75.440615 | N27: 0.052569908 | O27: 0.0017152633 | P27: =+J27/SUM($J27:$O27) -> 0.1972667 | Q27: =+K27/SUM($J27:$O27) -> 0.073159884 | R27: =+L27/SUM($J27:$O27) -> 0.72904881 | S27: =+N27/SUM($J27:$O27) -> 0.00050802911 | T27: =+P27*C27/1000/60/24.3*2*96485/-1/G27 -> 0.63334771 | U27: =+Q27*C27/1000/60/24.3*2*96485/-1/G27 -> 0.23488832 | W27: =+T27+U27 -> 0.86823603 | X27: =+K27/(K27+L27) -> 0.09119807
A28: Ag60 GDE in PTFE holder | B28: 60 | C28: =+'Flow rate'!E27 -> 75.1 | D28: 0.3 M Na2SO4 | E28: 0.05 M H2SO4 | F28: CCM-CEM | G28: -3 | H28: 45413.098 | I28: =+(H28-H$2)*24 -> 14.733333 | J28: 20.830375 | K28: 7.7672551 | L28: 74.740942 | N28: 0.052582051 | O28: 0.0014786619 | P28: =+J28/SUM($J28:$O28) -> 0.20146866 | Q28: =+K28/SUM($J28:$O28) -> 0.075123873 | R28: =+L28/SUM($J28:$O28) -> 0.7228846 | S28: =+N28/SUM($J28:$O28) -> 0.0005085667 | T28: =+P28*C28/1000/60/24.3*2*96485/-1/G28 -> 0.66751104 | U28: =+Q28*C28/1000/60/24.3*2*96485/-1/G28 -> 0.24890231 | W28: =+T28+U28 -> 0.91641335 | X28: =+K28/(K28+L28) -> 0.094139192 | Y28: =+SUM(K28:L28) -> 82.508197
A29: Ag60 GDE in PTFE holder | B29: 60 | C29: =+'Flow rate'!E28 -> 74.9 | D29: 0.3 M Na2SO4 | E29: 0.05 M H2SO4 | F29: CCM-CEM | G29: -3 | H29: 45413.115 | I29: =+(H29-H$2)*24 -> 15.15 | J29: 21.20627 | K29: 7.5293663 | L29: 74.482074 | N29: 0.052192938 | O29: 0.0011605619 | P29: =+J29/SUM($J29:$O29) -> 0.20534571 | Q29: =+K29/SUM($J29:$O29) -> 0.072908771 | R29: =+L29/SUM($J29:$O29) -> 0.72122888 | S29: =+N29/SUM($J29:$O29) -> 0.0005053975 | T29: =+P29*C29/1000/60/24.3*2*96485/-1/G29 -> 0.67854471 | U29: =+Q29*C29/1000/60/24.3*2*96485/-1/G29 -> 0.24091987 | W29: =+T29+U29 -> 0.91946458 | X29: =+K29/(K29+L29) -> 0.091808732
A30: Ag60 GDE in PTFE holder | B30: 60 | C30: =+'Flow rate'!E29 -> 74.7 | D30: 0.3 M Na2SO4 | E30: 0.05 M H2SO4 | F30: CCM-CEM | G30: -3 | H30: 45413.133 | I30: =+(H30-H$2)*24 -> 15.583333 | J30: 21.224671 | K30: 7.6989486 | L30: 74.449024 | N30: 0.052775571 | O30: 0.0014800297 | P30: =+J30/SUM($J30:$O30) -> 0.20521423 | Q30: =+K30/SUM($J30:$O30) -> 0.074438551 | R30: =+L30/SUM($J30:$O30) -> 0.71982264 | S30: =+N30/SUM($J30:$O30) -> 0.0005102693 | T30: =+P30*C30/1000/60/24.3*2*96485/-1/G30 -> 0.67629953 | U30: =+Q30*C30/1000/60/24.3*2*96485/-1/G30 -> 0.24531807 | W30: =+T30+U30 -> 0.9216176 | X30: =+K30/(K30+L30) -> 0.093720494 | Y30: =+SUM(K30:L30) -> 82.147973
A31: Ag60 GDE in PTFE holder | B31: 60 | C31: =+'Flow rate'!E30 -> 75.1 | D31: 0.3 M Na2SO4 | E31: 0.05 M H2SO4 | F31: CCM-CEM | G31: -3 | H31: 45413.151 | I31: =+(H31-H$2)*24 -> 16 | J31: 21.371326 | K31: 7.5746158 | L31: 74.197659 | N31: 0.0525524 | O31: 0.0014246497 | P31: =+J31/SUM($J31:$O31) -> 0.20709135 | Q31: =+K31/SUM($J31:$O31) -> 0.073399162 | R31: =+L31/SUM($J31:$O31) -> 0.71898644 | S31: =+N31/SUM($J31:$O31) -> 0.00050924063 | T31: =+P31*C31/1000/60/24.3*2*96485/-1/G31 -> 0.68614028 | U31: =+Q31*C31/1000/60/24.3*2*96485/-1/G31 -> 0.24318795 | W31: =+T31+U31 -> 0.92932824 | X31: =+K31/(K31+L31) -> 0.092630611
A32: Ag60 GDE in PTFE holder | B32: 60 | C32: =+'Flow rate'!E31 -> 58 | D32: 0.3 M Na2SO4 | E32: 0.05 M H2SO4 | F32: CCM-CEM | G32: -3 | H32: 45413.169 | I32: =+(H32-H$2)*24 -> 16.433333 | J32: 2.9077594 | K32: 4.2576203 | L32: 95.269455 | N32: 0.047549913 | O32: 0.0014145764 | P32: =+J32/SUM($J32:$O32) -> 0.028372869 | Q32: =+K32/SUM($J32:$O32) -> 0.041544326 | R32: =+L32/SUM($J32:$O32) -> 0.92960503 | S32: =+N32/SUM($J32:$O32) -> 0.00046397493 | T32: =+P32*C32/1000/60/24.3*2*96485/-1/G32 -> 0.072600943 | U32: =+Q32*C32/1000/60/24.3*2*96485/-1/G32 -> 0.10630427 | W32: =+T32+U32 -> 0.17890522 | X32: =+K32/(K32+L32) -> 0.042778514 | Y32: =+SUM(K32:L32) -> 99.527075
A33: Ag60 GDE in PTFE holder | B33: 60 | C33: =+'Flow rate'!E32 -> 59 | D33: 0.3 M Na2SO4 | E33: 0.05 M H2SO4 | F33: CCM-CEM | G33: -3 | H33: 45413.186 | I33: =+(H33-H$2)*24 -> 16.85 | J33: 2.5367995 | K33: 4.0784107 | L33: 95.714603 | N33: 0.047968421 | O33: 0.0014579295 | P33: =+J33/SUM($J33:$O33) -> 0.024778456 | Q33: =+K33/SUM($J33:$O33) -> 0.039836306 | R33: =+L33/SUM($J33:$O33) -> 0.93490246 | S33: =+N33/SUM($J33:$O33) -> 0.0004685366 | T33: =+P33*C33/1000/60/24.3*2*96485/-1/G33 -> 0.064496666 | U33: =+Q33*C33/1000/60/24.3*2*96485/-1/G33 -> 0.10369125 | W33: =+T33+U33 -> 0.16818791 | X33: =+K33/(K33+L33) -> 0.0408687
A34: Ag60 GDE in PTFE holder | B34: 60 | C34: =+'Flow rate'!E33 -> 59.4 | D34: 0.3 M Na2SO4 | E34: 0.05 M H2SO4 | F34: CCM-CEM | G34: -3 | H34: 45413.21 | I34: =+(H34-H$2)*24 -> 17.416667 | J34: 2.4728036 | K34: 3.9764234 | L34: 95.948287 | N34: 0.047933524 | O34: 0.0015036057 | P34: =+J34/SUM($J34:$O34) -> 0.024137405 | Q34: =+K34/SUM($J34:$O34) -> 0.038814463 | R34: =+L34/SUM($J34:$O34) -> 0.93656557 | S34: =+N34/SUM($J34:$O34) -> 0.00046788629 | T34: =+P34*C34/1000/60/24.3*2*96485/-1/G34 -> 0.063254007 | U34: =+Q34*C34/1000/60/24.3*2*96485/-1/G34 -> 0.10171641 | W34: =+T34+U34 -> 0.16497042 | X34: =+K34/(K34+L34) -> 0.039794194 | Y34: =+SUM(K34:L34) -> 99.924711
A35: Ag60 GDE in PTFE holder | B35: 60 | C35: =+'Flow rate'!E34 -> 59.9 | D35: 0.3 M Na2SO4 | E35: 0.05 M H2SO4 | F35: CCM-CEM | G35: -3 | H35: 45413.228 | I35: =+(H35-H$2)*24 -> 17.85 | J35: 2.4564959 | K35: 3.8970733 | L35: 96.072864 | N35: 0.046996245 | O35: 0.12201385 | P35: =+J35/SUM($J35:$O35) -> 0.023943519 | Q35: =+K35/SUM($J35:$O35) -> 0.037984857 | R35: =+L35/SUM($J35:$O35) -> 0.93642428 | S35: =+N35/SUM($J35:$O35) -> 0.00045807342 | T35: =+P35*C35/1000/60/24.3*2*96485/-1/G35 -> 0.063274076 | U35: =+Q35*C35/1000/60/24.3*2*96485/-1/G35 -> 0.10038027 | W35: =+T35+U35 -> 0.16365434 | X35: =+K35/(K35+L35) -> 0.038982452
A36: Ag60 GDE in PTFE holder | B36: 60 | C36: =+'Flow rate'!E35 -> 59.8 | D36: 0.3 M Na2SO4 | E36: 0.05 M H2SO4 | F36: CCM-CEM | G36: -3 | H36: 45413.245 | I36: =+(H36-H$2)*24 -> 18.266667 | J36: 2.4716375 | K36: 3.8369865 | L36: 96.131211 | N36: 0.048734488 | O36: 0.0013146203 | P36: =+J36/SUM($J36:$O36) -> 0.024115917 | Q36: =+K36/SUM($J36:$O36) -> 0.03743771 | R36: =+L36/SUM($J36:$O36) -> 0.93795804 | S36: =+N36/SUM($J36:$O36) -> 0.00047550535 | T36: =+P36*C36/1000/60/24.3*2*96485/-1/G36 -> 0.063623268 | U36: =+Q36*C36/1000/60/24.3*2*96485/-1/G36 -> 0.098769186 | W36: =+T36+U36 -> 0.16239245 | X36: =+K36/(K36+L36) -> 0.038382072 | Y36: =+SUM(K36:L36) -> 99.968197
A37: Ag60 GDE in PTFE holder | B37: 60 | C37: =+'Flow rate'!E36 -> 61 | D37: 0.3 M Na2SO4 | E37: 0.05 M H2SO4 | F37: CCM-CEM | G37: -3 | H37: 45413.263 | I37: =+(H37-H$2)*24 -> 18.7 | J37: 2.4877875 | K37: 3.8092008 | L37: 96.4794 | N37: 0.048555647 | O37: 0.001472786 | P37: =+J37/SUM($J37:$O37) -> 0.024194051 | Q37: =+K37/SUM($J37:$O37) -> 0.037044963 | R37: =+L37/SUM($J37:$O37) -> 0.93827445 | S37: =+N37/SUM($J37:$O37) -> 0.00047220985 | T37: =+P37*C37/1000/60/24.3*2*96485/-1/G37 -> 0.065110262 | U37: =+Q37*C37/1000/60/24.3*2*96485/-1/G37 -> 0.099694228 | W37: =+T37+U37 -> 0.16480449 | X37: =+K37/(K37+L37) -> 0.03798239
A38: Ag60 GDE in PTFE holder | B38: 60 | C38: =+'Flow rate'!E37 -> 60.5 | D38: 0.3 M Na2SO4 | E38: 0.05 M H2SO4 | F38: CCM-CEM | G38: -3 | H38: 45413.281 | I38: =+(H38-H$2)*24 -> 19.116667 | J38: 2.5053423 | K38: 3.7807613 | L38: 96.434047 | N38: 0.047018862 | O38: 0.0014107024 | P38: =+J38/SUM($J38:$O38) -> 0.024378485 | Q38: =+K38/SUM($J38:$O38) -> 0.036789078 | R38: =+L38/SUM($J38:$O38) -> 0.93836119 | S38: =+N38/SUM($J38:$O38) -> 0.00045752177 | T38: =+P38*C38/1000/60/24.3*2*96485/-1/G38 -> 0.065068845 | U38: =+Q38*C38/1000/60/24.3*2*96485/-1/G38 -> 0.098194078 | W38: =+T38+U38 -> 0.16326292 | X38: =+K38/(K38+L38) -> 0.037726573 | Y38: =+SUM(K38:L38) -> 100.21481
A39: Ag60 GDE in PTFE holder | B39: 60 | C39: =+'Flow rate'!E38 -> 61 | D39: 0.3 M Na2SO4 | E39: 0.05 M H2SO4 | F39: CCM-CEM | G39: -3 | H39: 45413.299 | I39: =+(H39-H$2)*24 -> 19.55 | J39: 2.5451087 | K39: 3.7211869 | L39: 96.538019 | N39: 0.047209272 | O39: 0.0012405407 | P39: =+J39/SUM($J39:$O39) -> 0.024745166 | Q39: =+K39/SUM($J39:$O39) -> 0.036179746 | R39: =+L39/SUM($J39:$O39) -> 0.93860403 | S39: =+N39/SUM($J39:$O39) -> 0.00045899857 | T39: =+P39*C39/1000/60/24.3*2*96485/-1/G39 -> 0.066593405 | U39: =+Q39*C39/1000/60/24.3*2*96485/-1/G39 -> 0.097365785 | W39: =+T39+U39 -> 0.16395919 | X39: =+K39/(K39+L39) -> 0.037115663
A40: Ag60 GDE in PTFE holder | B40: 60 | C40: =+'Flow rate'!E39 -> 60.5 | D40: 0.3 M Na2SO4 | E40: 0.05 M H2SO4 | F40: CCM-CEM | G40: -3 | H40: 45413.316 | I40: =+(H40-H$2)*24 -> 19.966667 | J40: 2.5785077 | K40: 3.680736 | L40: 96.512851 | N40: 0.048061856 | O40: 0.0012922871 | P40: =+J40/SUM($J40:$O40) -> 0.025077527 | Q40: =+K40/SUM($J40:$O40) -> 0.035797356 | R40: =+L40/SUM($J40:$O40) -> 0.93864512 | S40: =+N40/SUM($J40:$O40) -> 0.00046743026 | T40: =+P40*C40/1000/60/24.3*2*96485/-1/G40 -> 0.066934667 | U40: =+Q40*C40/1000/60/24.3*2*96485/-1/G40 -> 0.095547063 | W40: =+T40+U40 -> 0.16248173 | X40: =+K40/(K40+L40) -> 0.036736243 | Y40: =+SUM(K40:L40) -> 100.19359
...

Sheet Flow rate
B1: 0.9Mna2so4ph2 | C1: =+'Acidic Catholyte_Na2SO4'!H2 -> 45412.484 | D1: =+C1-2/24 -> 45412.401 | E1: {=INDEX(B$1:B$224233, MATCH(D1,A$1:A$224233,1) +0)} -> 51.4
A2: 45412.385 | B2: 0 | C2: =+'Acidic Catholyte_Na2SO4'!H3 -> 45412.497 | D2: =+C2-2/24 -> 45412.413 | E2: {=INDEX(B$1:B$224233, MATCH(D2,A$1:A$224233,1) +0)} -> 54.1
A3: 45412.386 | B3: 12.3 | C3: =+'Acidic Catholyte_Na2SO4'!H4 -> 45412.52 | D3: =+C3-2/24 -> 45412.437 | E3: {=INDEX(B$1:B$224233, MATCH(D3,A$1:A$224233,1) +0)} -> 56.4
A4: 45412.387 | B4: 50.2 | C4: =+'Acidic Catholyte_Na2SO4'!H5 -> 45412.556 | D4: =+C4-2/24 -> 45412.473 | E4: {=INDEX(B$1:B$224233, MATCH(D4,A$1:A$224233,1) +0)} -> 58.2
A5: 45412.387 | B5: 50.4 | C5: =+'Acidic Catholyte_Na2SO4'!H6 -> 45412.598 | D5: =+C5-2/24 -> 45412.515 | E5: {=INDEX(B$1:B$224233, MATCH(D5,A$1:A$224233,1) +0)} -> 58.7
A6: 45412.388 | B6: 50.1 | C6: =+'Acidic Catholyte_Na2SO4'!H7 -> 45412.64 | D6: =+C6-2/24 -> 45412.557 | E6: {=INDEX(B$1:B$224233, MATCH(D6,A$1:A$224233,1) +0)} -> 59.5
A7: 45412.389 | B7: 49.8 | C7: =+'Acidic Catholyte_Na2SO4'!H8 -> 45412.664 | D7: =+C7-2/24 -> 45412.581 | E7: {=INDEX(B$1:B$224233, MATCH(D7,A$1:A$224233,1) +0)} -> 59.3
A8: 45412.39 | B8: 49.7 | C8: =+'Acidic Catholyte_Na2SO4'!H9 -> 45412.688 | D8: =+C8-2/24 -> 45412.604 | E8: {=INDEX(B$1:B$224233, MATCH(D8,A$1:A$224233,1) +0)} -> 59.1
A9: 45412.39 | B9: 49.7 | C9: =+'Acidic Catholyte_Na2SO4'!H10 -> 45412.712 | D9: =+C9-2/24 -> 45412.628 | E9: {=INDEX(B$1:B$224233, MATCH(D9,A$1:A$224233,1) +0)} -> 58.8
A10: 45412.391 | B10: 49.5 | C10: =+'Acidic Catholyte_Na2SO4'!H11 -> 45412.748 | D10: =+C10-2/24 -> 45412.665 | E10: {=INDEX(B$1:B$224233, MATCH(D10,A$1:A$224233,1) +0)} -> 59.3
A11: 45412.392 | B11: 49.5 | C11: =+'Acidic Catholyte_Na2SO4'!H12 -> 45412.784 | D11: =+C11-2/24 -> 45412.701 | E11: {=INDEX(B$1:B$224233, MATCH(D11,A$1:A$224233,1) +0)} -> 59.6
A12: 45412.392 | B12: 49.7 | C12: =+'Acidic Catholyte_Na2SO4'!H13 -> 45412.82 | D12: =+C12-2/24 -> 45412.737 | E12: {=INDEX(B$1:B$224233, MATCH(D12,A$1:A$224233,1) +0)} -> 60.1
A13: 45412.393 | B13: 50 | C13: =+'Acidic Catholyte_Na2SO4'!H14 -> 45412.844 | D13: =+C13-2/24 -> 45412.76 | E13: {=INDEX(B$1:B$224233, MATCH(D13,A$1:A$224233,1) +0)} -> 60.1
... A124: 45412.47 | B124: 58.2 | C124: =+'Acidic Catholyte_Na2SO4'!H125 -> 45414.385 | D124: =+C124-2/24 -> 45414.301 | E124: {=INDEX(B$1:B$224233, MATCH(D124,A$1:A$224233,1) +0)} -> 62.4
A125: 45412.471 | B125: 58.1
A126: 45412.472 | B126: 58
A127: 45412.472 | B127: 58.1
A128: 45412.473 | B128: 58.2
A129: 45412.474 | B129: 57.9
A130: 45412.474 | B130: 58.3
A131: 45412.475 | B131: 58.1
A132: 45412.476 | B132: 58.4
A133: 45412.476 | B133: 58.3
A134: 45412.477 | B134: 58.5
A135: 45412.478 | B135: 58.4
A136: 45412.478 | B136: 58.3
... A2836: 45414.353 | B2836: 54.8
