Workbook

Sheet Sheet1
A1: Electrode | B1: Inlet flow rate | C1: Flow rate (ml min-1) | D1: Catholyte | E1: Anolyte | F1: Membrane | G1: Applied current / A | H1: Time | I1: Duration / h | J1: area(H2) | K1: area(CO) | L1: area(CO2) | M1: area(CH4) | N1: area(O2) | O1: area(N2) | P1: c(H2) | Q1: c(CO) | R1: c(CO2) | S1: c(O2) | T1: FE(H2) | U1: FE(CO) | V1: FE(CH4) | W1: Total FE | X1: Carbon efficiency
A2: Ag60 GDE in PTFE holder | B2: 60 | C2: =+'[1]Flow rate'!E64 -> 44.78069 | D2: K2SO4 | E2: 0.05 M H2SO4 | F2: CCM-CEM | G2: 0 | H2: 45454.672 | I2: 0 | J2: 0 | K2: 0 | L2: 0 | N2: 0 | O2: 0 | P2: =+J2/100 -> 0 | Q2: =+K2/100 -> 0 | R2: =+L2/100 -> 0 | S2: =+M2/100 -> 0 | T2: 0 | U2: 0 | W2: =+T2+U2 -> 0 | X2: =+R2/100 -> 0 | Y2: 0
A3: Ag60 GDE in PTFE holder | B3: 60 | C3: =+'[1]Flow rate'!E65 -> 51.516533 | D3: K2SO4 | E3: 0.05 M H2SO4 | F3: CCM-CEM | G3: -0.125 | H3: 45454.696 | I3: =+(H3-H$2)*24 -> 0.57728833 | J3: 0.0028694546 | K3: 0.032377699 | L3: 108.30673 | N3: 0.00082948936 | O3: 0.0096949361 | P3: =+J3/SUM($J3:$O3) -> 2.6482586e-05 | Q3: =+K3/SUM($J3:$O3) -> 0.00029881819 | R3: =+L3/SUM($J3:$O3) -> 0.99957757 | S3: =+N3/SUM($J3:$O3) -> 7.6554701e-06 | T3: =+P3*C3/1000/60/24.3*2*96485/-1/G3 -> 0.001444539 | U3: =+Q3*C3/1000/60/24.3*2*96485/-1/G3 -> 0.016299561 | W3: =+T3+U3 -> 0.0177441 | X3: =+R3/100 -> 0.0099957757
A4: Ag60 GDE in PTFE holder | B4: 60 | C4: =+'[1]Flow rate'!E66 -> 53.308384 | D4: K2SO4 | E4: 0.05 M H2SO4 | F4: CCM-CEM | G4: -0.125 | H4: 45454.707 | I4: =+(H4-H$2)*24 -> 0.82728833 | J4: 0.13146338 | K4: 1.6273237 | L4: 106.14662 | N4: 0.27825198 | O4: 0.30035101 | P4: =+J3/SUM($J3:$O3) -> 2.6482586e-05 | Q4: =+K3/SUM($J3:$O3) -> 0.00029881819 | R4: =+L3/SUM($J3:$O3) -> 0.99957757 | S4: =+N3/SUM($J3:$O3) -> 7.6554701e-06 | T4: =+P4*C4/1000/60/24.3*2*96485/-1/G4 -> 0.0014947831 | U4: =+Q4*C4/1000/60/24.3*2*96485/-1/G4 -> 0.016866493 | W4: =+T4+U4 -> 0.018361277 | X4: =+R4/100 -> 0.0099957757 | Y4: =+SUM(J3:L3) -> 108.34198
A5: Ag60 GDE in PTFE holder | B5: 60 | C5: =+'[1]Flow rate'!E67 -> 54.390244 | D5: K2SO4 | E5: 0.05 M H2SO4 | F5: CCM-CEM | G5: -0.125 | H5: 45454.717 | I5: =+(H5-H$2)*24 -> 1.0770106 | J5: 0.1503148 | K5: 1.599655 | L5: 106.26554 | N5: 0.23110405 | O5: 0.21001344 | P5: =+J4/SUM($J4:$O4) -> 0.0012118227 | Q5: =+K4/SUM($J4:$O4) -> 0.015000586 | R5: =+L4/SUM($J4:$O4) -> 0.97845406 | S5: =+N4/SUM($J4:$O4) -> 0.0025649124 | T5: =+P5*C5/1000/60/24.3*2*96485/-1/G5 -> 0.069788256 | U5: =+Q5*C5/1000/60/24.3*2*96485/-1/G5 -> 0.86387617 | W5: =+T5+U5 -> 0.93366443 | X5: =+R5/100 -> 0.0097845406
A6: Ag60 GDE in PTFE holder | B6: 60 | C6: =+'[1]Flow rate'!E68 -> 55.565525 | D6: K2SO4 | E6: 0.05 M H2SO4 | F6: CCM-CEM | G6: -0.125 | H6: 45454.728 | I6: =+(H6-H$2)*24 -> 1.3270106 | J6: 0.16607614 | K6: 1.5217607 | L6: 106.39263 | N6: 0.19050314 | O6: 0.15231471 | P6: =+J5/SUM($J5:$O5) -> 0.0013859439 | Q6: =+K5/SUM($J5:$O5) -> 0.01474926 | R6: =+L5/SUM($J5:$O5) -> 0.97979757 | S6: =+N5/SUM($J5:$O5) -> 0.0021308431 | T6: =+P6*C6/1000/60/24.3*2*96485/-1/G6 -> 0.081540491 | U6: =+Q6*C6/1000/60/24.3*2*96485/-1/G6 -> 0.86775658 | W6: =+T6+U6 -> 0.94929708 | X6: =+R6/100 -> 0.0097979757 | Y6: =+SUM(J5:L5) -> 108.01551
A7: Ag60 GDE in PTFE holder | B7: 60 | C7: =+'[1]Flow rate'!E69 -> 56.354196 | D7: K2SO4 | E7: 0.05 M H2SO4 | F7: CCM-CEM | G7: -0.125 | H7: 45454.738 | I7: =+(H7-H$2)*24 -> 1.5772883 | J7: 0.18367889 | K7: 1.4749185 | L7: 106.42111 | N7: 0.168642 | O7: 0.11501103 | P7: =+J6/SUM($J6:$O6) -> 0.0015317387 | Q7: =+K6/SUM($J6:$O6) -> 0.014035368 | R7: =+L6/SUM($J6:$O6) -> 0.98127105 | S7: =+N6/SUM($J6:$O6) -> 0.0017570316 | T7: =+P7*C7/1000/60/24.3*2*96485/-1/G7 -> 0.091397265 | U7: =+Q7*C7/1000/60/24.3*2*96485/-1/G7 -> 0.83747592 | W7: =+T7+U7 -> 0.92887318 | X7: =+R7/100 -> 0.0098127105
A8: Ag60 GDE in PTFE holder | B8: 60 | C8: =+'[1]Flow rate'!E70 -> 56.88977 | D8: K2SO4 | E8: 0.05 M H2SO4 | F8: CCM-CEM | G8: -0.125 | H8: 45454.748 | I8: =+(H8-H$2)*24 -> 1.8272883 | J8: 0.19478502 | K8: 1.4499084 | L8: 106.54012 | N8: 0.155848 | O8: 0.079870822 | P8: =+J7/SUM($J7:$O7) -> 0.0016950276 | Q8: =+K7/SUM($J7:$O7) -> 0.013610859 | R8: =+L7/SUM($J7:$O7) -> 0.9820765 | S8: =+N7/SUM($J7:$O7) -> 0.001556264 | T8: =+P8*C8/1000/60/24.3*2*96485/-1/G8 -> 0.10210176 | U8: =+Q8*C8/1000/60/24.3*2*96485/-1/G8 -> 0.81986429 | W8: =+T8+U8 -> 0.92196605 | X8: =+R8/100 -> 0.009820765 | Y8: =+SUM(J7:L7) -> 108.07971
A9: Ag60 GDE in PTFE holder | B9: 60 | C9: =+'[1]Flow rate'!E71 -> 58.791902 | D9: K2SO4 | E9: 0.05 M H2SO4 | F9: CCM-CEM | G9: -0.27 | H9: 45454.759 | I9: =+(H9-H$2)*24 -> 2.0775661 | J9: 0.20446015 | K9: 1.4232095 | L9: 106.49393 | N9: 0.14393509 | O9: 0.054845014 | P9: =+J8/SUM($J8:$O8) -> 0.0017965695 | Q9: =+K8/SUM($J8:$O8) -> 0.013373006 | R9: =+L8/SUM($J8:$O8) -> 0.98265631 | S9: =+N8/SUM($J8:$O8) -> 0.00143744 | T9: =+P9*C9/1000/60/24.3*2*96485/-1/G9 -> 0.051776186 | U9: =+Q9*C9/1000/60/24.3*2*96485/-1/G9 -> 0.38540296 | W9: =+T9+U9 -> 0.43717915 | X9: =+R9/100 -> 0.0098265631
A10: Ag60 GDE in PTFE holder | B10: 60 | C10: =+'[1]Flow rate'!E72 -> 58.900806 | D10: K2SO4 | E10: 0.05 M H2SO4 | F10: CCM-CEM | G10: -0.27 | H10: 45454.769 | I10: =+(H10-H$2)*24 -> 2.3275661 | J10: 0.0052385559 | K10: 1.7401759 | L10: 105.7328 | N10: 0.1442548 | O10: 0.038958494 | P10: =+J9/SUM($J9:$O9) -> 0.0018875502 | Q10: =+K9/SUM($J9:$O9) -> 0.01313889 | R10: =+L9/SUM($J9:$O9) -> 0.98313845 | S10: =+N9/SUM($J9:$O9) -> 0.0013287905 | T10: =+P10*C10/1000/60/24.3*2*96485/-1/G10 -> 0.054498965 | U10: =+Q10*C10/1000/60/24.3*2*96485/-1/G10 -> 0.37935728 | W10: =+T10+U10 -> 0.43385625 | X10: =+R10/100 -> 0.0098313845 | Y10: =+SUM(J9:L9) -> 108.1216
A11: Ag60 GDE in PTFE holder | B11: 60 | C11: =+'[1]Flow rate'!E73 -> 60.078346 | D11: K2SO4 | E11: 0.05 M H2SO4 | F11: CCM-CEM | G11: -0.27 | H11: 45454.78 | I11: =+(H11-H$2)*24 -> 2.5778439 | J11: 0.20323812 | K11: 2.9677776 | L11: 103.97956 | N11: 0.16901672 | O11: 0.029346275 | P11: =+J10/SUM($J10:$O10) -> 4.8657686e-05 | Q11: =+K10/SUM($J10:$O10) -> 0.016163411 | R11: =+L10/SUM($J10:$O10) -> 0.98208618 | S11: =+N10/SUM($J10:$O10) -> 0.0013398931 | T11: =+P11*C11/1000/60/24.3*2*96485/-1/G11 -> 0.0014329727 | U11: =+Q11*C11/1000/60/24.3*2*96485/-1/G11 -> 0.47601375 | W11: =+T11+U11 -> 0.47744672 | X11: =+R11/100 -> 0.0098208618
A12: Ag60 GDE in PTFE holder | B12: 60 | C12: =+'[1]Flow rate'!E74 -> 59.894937 | D12: K2SO4 | E12: 0.05 M H2SO4 | F12: CCM-CEM | G12: -0.27 | H12: 45454.79 | I12: =+(H12-H$2)*24 -> 2.8278439 | J12: 0.20577968 | K12: 3.1468316 | L12: 103.51075 | N12: 0.16539802 | O12: 0.022442172 | P12: =+J11/SUM($J11:$O11) -> 0.0018932476 | Q12: =+K11/SUM($J11:$O11) -> 0.027646083 | R12: =+L11/SUM($J11:$O11) -> 0.96861284 | S12: =+N11/SUM($J11:$O11) -> 0.0015744611 | T12: =+P12*C12/1000/60/24.3*2*96485/-1/G12 -> 0.05558608 | U12: =+Q12*C12/1000/60/24.3*2*96485/-1/G12 -> 0.81169381 | W12: =+T12+U12 -> 0.86727989 | X12: =+R12/100 -> 0.0096861284 | Y12: =+SUM(J11:L11) -> 107.15057
A13: Ag60 GDE in PTFE holder | B13: 60 | C13: =+'[1]Flow rate'!E75 -> 60.134958 | D13: K2SO4 | E13: 0.05 M H2SO4 | F13: CCM-CEM | G13: -0.27 | H13: 45454.801 | I13: =+(H13-H$2)*24 -> 3.0778439 | J13: 0.211829 | K13: 3.1683802 | L13: 103.63624 | N13: 0.16239537 | O13: 0.01215081 | P13: =+J12/SUM($J12:$O12) -> 0.0019222547 | Q13: =+K12/SUM($J12:$O12) -> 0.029395573 | R13: =+L12/SUM($J12:$O12) -> 0.9669275 | S13: =+N12/SUM($J12:$O12) -> 0.0015450365 | T13: =+P13*C13/1000/60/24.3*2*96485/-1/G13 -> 0.056663899 | U13: =+Q13*C13/1000/60/24.3*2*96485/-1/G13 -> 0.86651774 | W13: =+T13+U13 -> 0.92318164 | X13: =+R13/100 -> 0.009669275
A14: Ag60 GDE in PTFE holder | B14: 60 | C14: =+'[1]Flow rate'!E76 -> 60.602149 | D14: K2SO4 | E14: 0.05 M H2SO4 | F14: CCM-CEM | G14: -0.27 | H14: 45454.811 | I14: =+(H14-H$2)*24 -> 3.3281217 | J14: 0.21826976 | K14: 3.1859621 | L14: 103.55571 | N14: 0.16261569 | O14: 0.012361975 | P14: =+J13/SUM($J13:$O13) -> 0.0019761827 | Q14: =+K13/SUM($J13:$O13) -> 0.029558267 | R14: =+L13/SUM($J13:$O13) -> 0.96683718 | S14: =+N13/SUM($J13:$O13) -> 0.0015150094 | T14: =+P14*C14/1000/60/24.3*2*96485/-1/G14 -> 0.058706154 | U14: =+Q14*C14/1000/60/24.3*2*96485/-1/G14 -> 0.87808287 | W14: =+T14+U14 -> 0.93678902 | X14: =+R14/100 -> 0.0096683718 | Y14: =+SUM(J13:L13) -> 107.01645
A15: Ag60 GDE in PTFE holder | B15: 60 | C15: =+'[1]Flow rate'!E77 -> 60.442654 | D15: K2SO4 | E15: 0.05 M H2SO4 | F15: CCM-CEM | G15: -0.27 | H15: 45454.821 | I15: =+(H15-H$2)*24 -> 3.5781217 | J15: 0.22269897 | K15: 3.1733957 | L15: 103.58003 | N15: 0.15978807 | O15: 0.0029460499 | P15: =+J14/SUM($J14:$O14) -> 0.0020373354 | Q15: =+K14/SUM($J14:$O14) -> 0.029737849 | R15: =+L14/SUM($J14:$O14) -> 0.96659157 | S15: =+N14/SUM($J14:$O14) -> 0.0015178589 | T15: =+P15*C15/1000/60/24.3*2*96485/-1/G15 -> 0.060363522 | U15: =+Q15*C15/1000/60/24.3*2*96485/-1/G15 -> 0.88109268 | W15: =+T15+U15 -> 0.9414562 | X15: =+R15/100 -> 0.0096659157
A16: Ag60 GDE in PTFE holder | B16: 60 | C16: =+'[1]Flow rate'!E78 -> 60.726002 | D16: K2SO4 | E16: 0.05 M H2SO4 | F16: CCM-CEM | G16: -0.27 | H16: 45454.832 | I16: =+(H16-H$2)*24 -> 3.8281217 | J16: 0.22765965 | K16: 3.1635488 | L16: 103.7133 | N16: 0.17072322 | O16: 0.018451923 | P16: =+J15/SUM($J15:$O15) -> 0.0020786013 | Q16: =+K15/SUM($J15:$O15) -> 0.029619464 | R16: =+L15/SUM($J15:$O15) -> 0.96678303 | S16: =+N15/SUM($J15:$O15) -> 0.0014914109 | T16: =+P16*C16/1000/60/24.3*2*96485/-1/G16 -> 0.061874882 | U16: =+Q16*C16/1000/60/24.3*2*96485/-1/G16 -> 0.88169911 | W16: =+T16+U16 -> 0.94357399 | X16: =+R16/100 -> 0.0096678303 | Y16: =+SUM(J15:L15) -> 106.97613
A17: Ag60 GDE in PTFE holder | B17: 60 | C17: =+'[1]Flow rate'!E79 -> 62.879046 | D17: K2SO4 | E17: 0.05 M H2SO4 | F17: CCM-CEM | G17: -0.52 | H17: 45454.842 | I17: =+(H17-H$2)*24 -> 4.0783994 | J17: 0.23000253 | K17: 3.1641912 | L17: 103.67851 | N17: 0.15977573 | O17: n.a. | P17: =+J16/SUM($J16:$O16) -> 0.0021218365 | Q17: =+K16/SUM($J16:$O16) -> 0.029484949 | R17: =+L16/SUM($J16:$O16) -> 0.96663006 | S17: =+N16/SUM($J16:$O16) -> 0.0015911768 | T17: =+P17*C17/1000/60/24.3*2*96485/-1/G17 -> 0.033958366 | U17: =+Q17*C17/1000/60/24.3*2*96485/-1/G17 -> 0.471884 | W17: =+T17+U17 -> 0.50584236 | X17: =+R17/100 -> 0.0096663006
A18: Ag60 GDE in PTFE holder | B18: 60 | C18: =+'[1]Flow rate'!E80 -> 63.185506 | D18: K2SO4 | E18: 0.05 M H2SO4 | F18: CCM-CEM | G18: -0.52 | H18: 45454.853 | I18: =+(H18-H$2)*24 -> 4.3286772 | J18: 0.25804003 | K18: 3.6840211 | L18: 103.07021 | N18: 0.18102851 | O18: 0.010328239 | P18: =+J17/SUM($J17:$O17) -> 0.0021448961 | Q18: =+K17/SUM($J17:$O17) -> 0.029507768 | R18: =+L17/SUM($J17:$O17) -> 0.96685734 | S18: =+N17/SUM($J17:$O17) -> 0.0014899938 | T18: =+P18*C18/1000/60/24.3*2*96485/-1/G18 -> 0.034494723 | U18: =+Q18*C18/1000/60/24.3*2*96485/-1/G18 -> 0.47455085 | W18: =+T18+U18 -> 0.50904557 | X18: =+R18/100 -> 0.0096685734 | Y18: =+SUM(J17:L17) -> 107.07271
A19: Ag60 GDE in PTFE holder | B19: 60 | C19: =+'[1]Flow rate'!E81 -> 62.954716 | D19: K2SO4 | E19: 0.05 M H2SO4 | F19: CCM-CEM | G19: -0.52 | H19: 45454.863 | I19: =+(H19-H$2)*24 -> 4.5786772 | J19: 0.33643389 | K19: 5.5318422 | L19: 100.57118 | N19: 0.21648814 | O19: n.a. | P19: =+J18/SUM($J18:$O18) -> 0.0024070083 | Q19: =+K18/SUM($J18:$O18) -> 0.034364705 | R19: =+L18/SUM($J18:$O18) -> 0.9614433 | S19: =+N18/SUM($J18:$O18) -> 0.0016886416 | T19: =+P19*C19/1000/60/24.3*2*96485/-1/G19 -> 0.038568682 | U19: =+Q19*C19/1000/60/24.3*2*96485/-1/G19 -> 0.55064262 | W19: =+T19+U19 -> 0.5892113 | X19: =+R19/100 -> 0.009614433
A20: Ag60 GDE in PTFE holder | B20: 60 | C20: =+'[1]Flow rate'!E82 -> 62.693566 | D20: K2SO4 | E20: 0.05 M H2SO4 | F20: CCM-CEM | G20: -0.52 | H20: 45454.874 | I20: =+(H20-H$2)*24 -> 4.8292328 | J20: 0.35752044 | K20: 5.8355742 | L20: 100.04851 | N20: 0.22834485 | O20: 0.00024657073 | P20: =+J19/SUM($J19:$O19) -> 0.0031543848 | Q20: =+K19/SUM($J19:$O19) -> 0.051866234 | R20: =+L19/SUM($J19:$O19) -> 0.9429496 | S20: =+N19/SUM($J19:$O19) -> 0.0020297804 | T20: =+P20*C20/1000/60/24.3*2*96485/-1/G20 -> 0.050334594 | U20: =+Q20*C20/1000/60/24.3*2*96485/-1/G20 -> 0.82763075 | W20: =+T20+U20 -> 0.87796535 | X20: =+R20/100 -> 0.009429496 | Y20: =+SUM(J19:L19) -> 106.43946
A21: Ag60 GDE in PTFE holder | B21: 60 | C21: =+'[1]Flow rate'!E83 -> 63.117385 | D21: K2SO4 | E21: 0.05 M H2SO4 | F21: CCM-CEM | G21: -0.52 | H21: 45454.884 | I21: =+(H21-H$2)*24 -> 5.078955 | J21: 0.36638062 | K21: 5.8790098 | L21: 99.945422 | N21: 0.23069043 | O21: 0.00034778723 | P21: =+J20/SUM($J20:$O20) -> 0.0033579392 | Q21: =+K20/SUM($J20:$O20) -> 0.054809462 | R21: =+L20/SUM($J20:$O20) -> 0.9396856 | S21: =+N20/SUM($J20:$O20) -> 0.0021446833 | T21: =+P21*C21/1000/60/24.3*2*96485/-1/G21 -> 0.053944945 | U21: =+Q21*C21/1000/60/24.3*2*96485/-1/G21 -> 0.88050832 | W21: =+T21+U21 -> 0.93445326 | X21: =+R21/100 -> 0.009396856
A22: Ag60 GDE in PTFE holder | B22: 60 | C22: =+'[1]Flow rate'!E84 -> 62.903899 | D22: K2SO4 | E22: 0.05 M H2SO4 | F22: CCM-CEM | G22: -0.52 | H22: 45454.894 | I22: =+(H22-H$2)*24 -> 5.3292328 | J22: 0.36928856 | K22: 5.8847139 | L22: 99.826951 | N22: 0.23752749 | O22: 0.005428496 | P22: =+J21/SUM($J21:$O21) -> 0.0034427199 | Q22: =+K21/SUM($J21:$O21) -> 0.055242507 | R22: =+L21/SUM($J21:$O21) -> 0.93914381 | S22: =+N21/SUM($J21:$O21) -> 0.002167698 | T22: =+P22*C22/1000/60/24.3*2*96485/-1/G22 -> 0.05511987 | U22: =+Q22*C22/1000/60/24.3*2*96485/-1/G22 -> 0.88446342 | W22: =+T22+U22 -> 0.93958329 | X22: =+R22/100 -> 0.0093914381 | Y22: =+SUM(J21:L21) -> 106.19081
A23: Ag60 GDE in PTFE holder | B23: 60 | C23: =+'[1]Flow rate'!E85 -> 63.402572 | D23: K2SO4 | E23: 0.05 M H2SO4 | F23: CCM-CEM | G23: -0.52 | H23: 45454.905 | I23: =+(H23-H$2)*24 -> 5.5792328 | J23: 0.37130367 | K23: 5.914238 | L23: 100.00149 | N23: 0.23692912 | O23: n.a. | P23: =+J22/SUM($J22:$O22) -> 0.003473241 | Q23: =+K22/SUM($J22:$O22) -> 0.055347042 | R23: =+L22/SUM($J22:$O22) -> 0.93889466 | S23: =+N22/SUM($J22:$O22) -> 0.0022339989 | T23: =+P23*C23/1000/60/24.3*2*96485/-1/G23 -> 0.056049368 | U23: =+Q23*C23/1000/60/24.3*2*96485/-1/G23 -> 0.89316196 | W23: =+T23+U23 -> 0.94921133 | X23: =+R23/100 -> 0.0093889466
A24: Ag60 GDE in PTFE holder | B24: 60 | C24: =+'[1]Flow rate'!E86 -> 62.917591 | D24: K2SO4 | E24: 0.05 M H2SO4 | F24: CCM-CEM | G24: -0.52 | H24: 45454.915 | I24: =+(H24-H$2)*24 -> 5.8295106 | J24: 0.36759966 | K24: 5.929697 | L24: 99.808484 | N24: 0.24196727 | O24: 0.0017598038 | P24: =+J23/SUM($J23:$O23) -> 0.0034856353 | Q24: =+K23/SUM($J23:$O23) -> 0.055520262 | R24: =+L23/SUM($J23:$O23) -> 0.93876992 | S24: =+N23/SUM($J23:$O23) -> 0.0022241862 | T24: =+P24*C24/1000/60/24.3*2*96485/-1/G24 -> 0.055819116 | U24: =+Q24*C24/1000/60/24.3*2*96485/-1/G24 -> 0.88910391 | W24: =+T24+U24 -> 0.94492303 | X24: =+R24/100 -> 0.0093876992 | Y24: =+SUM(J23:L23) -> 106.28703
A25: Ag60 GDE in PTFE holder | B25: 60 | C25: =+'[1]Flow rate'!E87 -> 65.450352 | D25: K2SO4 | E25: 0.05 M H2SO4 | F25: CCM-CEM | G25: -0.77 | H25: 45454.926 | I25: =+(H25-H$2)*24 -> 6.0795106 | J25: 0.36470344 | K25: 5.9532752 | L25: 99.969997 | N25: 0.24314125 | O25: n.a. | P25: =+J24/SUM($J24:$O24) -> 0.0034565243 | Q25: =+K24/SUM($J24:$O24) -> 0.055756695 | R25: =+L24/SUM($J24:$O24) -> 0.93849503 | S25: =+N24/SUM($J24:$O24) -> 0.0022752082 | T25: =+P25*C25/1000/60/24.3*2*96485/-1/G25 -> 0.038885989 | U25: =+Q25*C25/1000/60/24.3*2*96485/-1/G25 -> 0.62726427 | W25: =+T25+U25 -> 0.66615026 | X25: =+R25/100 -> 0.0093849503
A26: Ag60 GDE in PTFE holder | B26: 60 | C26: =+'[1]Flow rate'!E88 -> 65.004163 | D26: K2SO4 | E26: 0.05 M H2SO4 | F26: CCM-CEM | G26: -0.77 | H26: 45454.936 | I26: =+(H26-H$2)*24 -> 6.3300661 | J26: 0.47767847 | K26: 6.619044 | L26: 99.063024 | N26: 0.2559554 | O26: n.a. | P26: =+J25/SUM($J25:$O25) -> 0.0034234452 | Q26: =+K25/SUM($J25:$O25) -> 0.05588297 | R26: =+L25/SUM($J25:$O25) -> 0.93841123 | S26: =+N25/SUM($J25:$O25) -> 0.0022823495 | T26: =+P26*C26/1000/60/24.3*2*96485/-1/G26 -> 0.038251292 | U26: =+Q26*C26/1000/60/24.3*2*96485/-1/G26 -> 0.624399 | W26: =+T26+U26 -> 0.6626503 | X26: =+R26/100 -> 0.0093841123 | Y26: =+SUM(J25:L25) -> 106.28798
A27: Ag60 GDE in PTFE holder | B27: 60 | C27: =+'[1]Flow rate'!E89 -> 65.245939 | D27: K2SO4 | E27: 0.05 M H2SO4 | F27: CCM-CEM | G27: -0.77 | H27: 45454.946 | I27: =+(H27-H$2)*24 -> 6.5803439 | J27: 0.83330564 | K27: 8.1128706 | L27: 96.916862 | N27: 0.30898946 | O27: 0.00041573755 | P27: =+J26/SUM($J26:$O26) -> 0.0044887968 | Q27: =+K26/SUM($J26:$O26) -> 0.062199881 | R27: =+L26/SUM($J26:$O26) -> 0.93090608 | S27: =+N26/SUM($J26:$O26) -> 0.0024052409 | T27: =+P27*C27/1000/60/24.3*2*96485/-1/G27 -> 0.050341365 | U27: =+Q27*C27/1000/60/24.3*2*96485/-1/G27 -> 0.69756484 | W27: =+T27+U27 -> 0.74790621 | X27: =+R27/100 -> 0.0093090608
A28: Ag60 GDE in PTFE holder | B28: 60 | C28: =+'[1]Flow rate'!E90 -> 65.050959 | D28: K2SO4 | E28: 0.05 M H2SO4 | F28: CCM-CEM | G28: -0.77 | H28: 45454.957 | I28: =+(H28-H$2)*24 -> 6.8300661 | J28: 0.91457432 | K28: 8.3594312 | L28: 95.876412 | N28: 0.31887554 | O28: 0.00070826218 | P28: =+J27/SUM($J27:$O27) -> 0.0078486057 | Q28: =+K27/SUM($J27:$O27) -> 0.076412206 | R28: =+L27/SUM($J27:$O27) -> 0.91282501 | S28: =+N27/SUM($J27:$O27) -> 0.0029102604 | T28: =+P28*C28/1000/60/24.3*2*96485/-1/G28 -> 0.087758211 | U28: =+Q28*C28/1000/60/24.3*2*96485/-1/G28 -> 0.8543936 | W28: =+T28+U28 -> 0.94215181 | X28: =+R28/100 -> 0.0091282501 | Y28: =+SUM(J27:L27) -> 105.86304
A29: Ag60 GDE in PTFE holder | B29: 60 | C29: =+'[1]Flow rate'!E91 -> 64.875403 | D29: K2SO4 | E29: 0.05 M H2SO4 | F29: CCM-CEM | G29: -0.77 | H29: 45454.967 | I29: =+(H29-H$2)*24 -> 7.0800661 | J29: 0.92973929 | K29: 8.3973902 | L29: 95.990191 | N29: 0.32512241 | O29: n.a. | P29: =+J28/SUM($J28:$O28) -> 0.0086714165 | Q29: =+K28/SUM($J28:$O28) -> 0.079258851 | R29: =+L28/SUM($J28:$O28) -> 0.90903964 | S29: =+N28/SUM($J28:$O28) -> 0.0030233767 | T29: =+P29*C29/1000/60/24.3*2*96485/-1/G29 -> 0.096696703 | U29: =+Q29*C29/1000/60/24.3*2*96485/-1/G29 -> 0.88383132 | W29: =+T29+U29 -> 0.98052803 | X29: =+R29/100 -> 0.0090903964
A30: Ag60 GDE in PTFE holder | B30: 60 | C30: =+'[1]Flow rate'!E92 -> 65.28201 | D30: K2SO4 | E30: 0.05 M H2SO4 | F30: CCM-CEM | G30: -0.77 | H30: 45454.978 | I30: =+(H30-H$2)*24 -> 7.3306217 | J30: 0.93846358 | K30: 8.5276493 | L30: 96.295355 | N30: 0.32402077 | O30: 0.0005417129 | P30: =+J29/SUM($J29:$O29) -> 0.0088008121 | Q30: =+K29/SUM($J29:$O29) -> 0.079488792 | R30: =+L29/SUM($J29:$O29) -> 0.90863282 | S30: =+N29/SUM($J29:$O29) -> 0.0030775738 | T30: =+P30*C30/1000/60/24.3*2*96485/-1/G30 -> 0.098754709 | U30: =+Q30*C30/1000/60/24.3*2*96485/-1/G30 -> 0.89195093 | W30: =+T30+U30 -> 0.99070564 | X30: =+R30/100 -> 0.0090863282 | Y30: =+SUM(J29:L29) -> 105.31732
A31: Ag60 GDE in PTFE holder | B31: 60 | C31: =+'[1]Flow rate'!E93 -> 64.931041 | D31: K2SO4 | E31: 0.05 M H2SO4 | F31: CCM-CEM | G31: -0.77 | H31: 45454.988 | I31: =+(H31-H$2)*24 -> 7.5808994 | J31: 0.94992444 | K31: 8.5423023 | L31: 96.205921 | N31: 0.32523459 | O31: 0.0017379898 | P31: =+J30/SUM($J30:$O30) -> 0.0088462504 | Q31: =+K30/SUM($J30:$O30) -> 0.080384281 | R31: =+L30/SUM($J30:$O30) -> 0.90771004 | S31: =+N30/SUM($J30:$O30) -> 0.0030543208 | T31: =+P31*C31/1000/60/24.3*2*96485/-1/G31 -> 0.09873091 | U31: =+Q31*C31/1000/60/24.3*2*96485/-1/G31 -> 0.89714997 | W31: =+T31+U31 -> 0.99588088 | X31: =+R31/100 -> 0.0090771004
A32: Ag60 GDE in PTFE holder | B32: 60 | C32: =+'[1]Flow rate'!E94 -> 64.720758 | D32: K2SO4 | E32: 0.05 M H2SO4 | F32: CCM-CEM | G32: -0.77 | H32: 45454.999 | I32: =+(H32-H$2)*24 -> 7.8308994 | J32: 0.95901365 | K32: 8.5869607 | L32: 96.285564 | N32: 0.33108006 | O32: n.a. | P32: =+J31/SUM($J31:$O31) -> 0.0089594281 | Q32: =+K31/SUM($J31:$O31) -> 0.080568664 | R32: =+L31/SUM($J31:$O31) -> 0.90738799 | S32: =+N31/SUM($J31:$O31) -> 0.0030675239 | T32: =+P32*C32/1000/60/24.3*2*96485/-1/G32 -> 0.099670223 | U32: =+Q32*C32/1000/60/24.3*2*96485/-1/G32 -> 0.89629569 | W32: =+T32+U32 -> 0.99596591 | X32: =+R32/100 -> 0.0090738799 | Y32: =+SUM(J31:L31) -> 105.69815
A33: Ag60 GDE in PTFE holder | B33: 60 | C33: =+'[1]Flow rate'!E95 -> 67.122949 | D33: K2SO4 | E33: 0.05 M H2SO4 | F33: CCM-CEM | G33: -1.1 | H33: 45455.009 | I33: =+(H33-H$2)*24 -> 8.0808994 | J33: 0.97547118 | K33: 8.6141614 | L33: 96.22015 | N33: 0.33105705 | O33: n.a. | P33: =+J32/SUM($J32:$O32) -> 0.00903344 | Q33: =+K32/SUM($J32:$O32) -> 0.080884975 | R33: =+L32/SUM($J32:$O32) -> 0.90696297 | S33: =+N32/SUM($J32:$O32) -> 0.0031186124 | T33: =+P33*C33/1000/60/24.3*2*96485/-1/G33 -> 0.072956465 | U33: =+Q33*C33/1000/60/24.3*2*96485/-1/G33 -> 0.65324857 | W33: =+T33+U33 -> 0.72620504 | X33: =+R33/100 -> 0.0090696297
A34: Ag60 GDE in PTFE holder | B34: 60 | C34: =+'[1]Flow rate'!E96 -> 66.493643 | D34: K2SO4 | E34: 0.05 M H2SO4 | F34: CCM-CEM | G34: -1.1 | H34: 45455.019 | I34: =+(H34-H$2)*24 -> 8.3308994 | J34: 1.2233444 | K34: 8.7972801 | L34: 95.503018 | N34: 0.35318998 | O34: 0.00082071298 | P34: =+J33/SUM($J33:$O33) -> 0.0091903473 | Q34: =+K33/SUM($J33:$O33) -> 0.081157842 | R34: =+L33/SUM($J33:$O33) -> 0.90653278 | S34: =+N33/SUM($J33:$O33) -> 0.0031190356 | T34: =+P34*C34/1000/60/24.3*2*96485/-1/G34 -> 0.073527812 | U34: =+Q34*C34/1000/60/24.3*2*96485/-1/G34 -> 0.64930718 | W34: =+T34+U34 -> 0.72283499 | X34: =+R34/100 -> 0.0090653278 | Y34: =+SUM(J33:L33) -> 105.80978
A35: Ag60 GDE in PTFE holder | B35: 60 | C35: =+'[1]Flow rate'!E97 -> 66.747988 | D35: K2SO4 | E35: 0.05 M H2SO4 | F35: CCM-CEM | G35: -1.1 | H35: 45455.03 | I35: =+(H35-H$2)*24 -> 8.5811772 | J35: 2.0598964 | K35: 9.7541133 | L35: 93.301086 | N35: 0.39630321 | O35: 0.0016444078 | P35: =+J34/SUM($J34:$O34) -> 0.011554321 | Q35: =+K34/SUM($J34:$O34) -> 0.083089111 | R35: =+L34/SUM($J34:$O34) -> 0.90201298 | S35: =+N34/SUM($J34:$O34) -> 0.0033358312 | T35: =+P35*C35/1000/60/24.3*2*96485/-1/G35 -> 0.092794491 | U35: =+Q35*C35/1000/60/24.3*2*96485/-1/G35 -> 0.66730116 | W35: =+T35+U35 -> 0.76009565 | X35: =+R35/100 -> 0.0090201298
A36: Ag60 GDE in PTFE holder | B36: 60 | C36: =+'[1]Flow rate'!E98 -> 66.157108 | D36: K2SO4 | E36: 0.05 M H2SO4 | F36: CCM-CEM | G36: -1.1 | H36: 45455.04 | I36: =+(H36-H$2)*24 -> 8.8317328 | J36: 2.2312171 | K36: 9.9102468 | L36: 92.941364 | N36: 0.40670704 | O36: n.a. | P36: =+J35/SUM($J35:$O35) -> 0.01952267 | Q36: =+K35/SUM($J35:$O35) -> 0.092444622 | R36: =+L35/SUM($J35:$O35) -> 0.88426116 | S36: =+N35/SUM($J35:$O35) -> 0.0037559642 | T36: =+P36*C36/1000/60/24.3*2*96485/-1/G36 -> 0.15540154 | U36: =+Q36*C36/1000/60/24.3*2*96485/-1/G36 -> 0.73586433 | W36: =+T36+U36 -> 0.89126587 | X36: =+R36/100 -> 0.0088426116 | Y36: =+SUM(J35:L35) -> 105.1151
A37: Ag60 GDE in PTFE holder | B37: 60 | C37: =+'[1]Flow rate'!E99 -> 66.338057 | D37: K2SO4 | E37: 0.05 M H2SO4 | F37: CCM-CEM | G37: -1.1 | H37: 45455.051 | I37: =+(H37-H$2)*24 -> 9.0817328 | J37: 2.3274456 | K37: 9.7441599 | L37: 92.817821 | N37: 0.41413227 | O37: 0.010582565 | P37: =+J36/SUM($J36:$O36) -> 0.021151075 | Q37: =+K36/SUM($J36:$O36) -> 0.093945307 | R37: =+L36/SUM($J36:$O36) -> 0.88104819 | S37: =+N36/SUM($J36:$O36) -> 0.0038554254 | T37: =+P37*C37/1000/60/24.3*2*96485/-1/G37 -> 0.16882423 | U37: =+Q37*C37/1000/60/24.3*2*96485/-1/G37 -> 0.74985523 | W37: =+T37+U37 -> 0.91867947 | X37: =+R37/100 -> 0.0088104819
A38: Ag60 GDE in PTFE holder | B38: 60 | C38: =+'[1]Flow rate'!E100 -> 65.962505 | D38: K2SO4 | E38: 0.05 M H2SO4 | F38: CCM-CEM | G38: -1.1 | H38: 45455.061 | I38: =+(H38-H$2)*24 -> 9.3320106 | J38: 2.4133175 | K38: 9.7222074 | L38: 92.876991 | N38: 0.41371533 | O38: 0.00043809681 | P38: =+J37/SUM($J37:$O37) -> 0.022100029 | Q38: =+K37/SUM($J37:$O37) -> 0.092524706 | R38: =+L37/SUM($J37:$O37) -> 0.88134243 | S38: =+N37/SUM($J37:$O37) -> 0.003932352 | T38: =+P38*C38/1000/60/24.3*2*96485/-1/G38 -> 0.17539999 | U38: =+Q38*C38/1000/60/24.3*2*96485/-1/G38 -> 0.73433536 | W38: =+T38+U38 -> 0.90973535 | X38: =+R38/100 -> 0.0088134243 | Y38: =+SUM(J37:L37) -> 104.88943
A39: Ag60 GDE in PTFE holder | B39: 60 | C39: =+'[1]Flow rate'!E101 -> 66.749398 | D39: K2SO4 | E39: 0.05 M H2SO4 | F39: CCM-CEM | G39: -1.1 | H39: 45455.072 | I39: =+(H39-H$2)*24 -> 9.5822883 | J39: 2.4457602 | K39: 9.7658153 | L39: 92.73024 | N39: 0.41173726 | O39: n.a. | P39: =+J38/SUM($J38:$O38) -> 0.022890959 | Q39: =+K38/SUM($J38:$O38) -> 0.092217724 | R39: =+L38/SUM($J38:$O38) -> 0.88096296 | S39: =+N38/SUM($J38:$O38) -> 0.0039242 | T39: =+P39*C39/1000/60/24.3*2*96485/-1/G39 -> 0.18384462 | U39: =+Q39*C39/1000/60/24.3*2*96485/-1/G39 -> 0.74063007 | W39: =+T39+U39 -> 0.92447469 | X39: =+R39/100 -> 0.0088096296
A40: Ag60 GDE in PTFE holder | B40: 60 | C40: =+'[1]Flow rate'!E102 -> 62.6125 | D40: K2SO4 | E40: 0.05 M H2SO4 | F40: CCM-CEM | G40: -1.1 | H40: 45455.082 | I40: =+(H40-H$2)*24 -> 9.8325661 | J40: 2.4972282 | K40: 9.4043284 | L40: 92.885623 | N40: 0.41572568 | O40: n.a. | P40: =+J39/SUM($J39:$O39) -> 0.023214786 | Q40: =+K39/SUM($J39:$O39) -> 0.092695643 | R40: =+L39/SUM($J39:$O39) -> 0.88018142 | S40: =+N39/SUM($J39:$O39) -> 0.0039081479 | T40: =+P40*C40/1000/60/24.3*2*96485/-1/G40 -> 0.17489014 | U40: =+Q40*C40/1000/60/24.3*2*96485/-1/G40 -> 0.6983288 | W40: =+T40+U40 -> 0.87321894 | X40: =+R40/100 -> 0.0088018142 | Y40: =+SUM(J39:L39) -> 104.94182
...

Sheet Flow rate
B1: 0.9Mk2so4pH3 | C1: =+Sheet1!H2 -> 45454.672 | D1: =+C1-2/24 -> 45454.589 | E1: {=INDEX(B$1:B$224233, MATCH(D1,A$1:A$224233,1) +0)} -> 44.78069
A2: 45454.578 | B2: 0 | C2: =+Sheet1!H3 -> 45454.696 | D2: =+C2-2/24 -> 45454.613 | E2: {=INDEX(B$1:B$224233, MATCH(D2,A$1:A$224233,1) +0)} -> 52.910475
A3: 45454.578 | B3: 13.130095 | C3: =+Sheet1!H4 -> 45454.707 | D3: =+C3-2/24 -> 45454.623 | E3: {=INDEX(B$1:B$224233, MATCH(D3,A$1:A$224233,1) +0)} -> 55.012857
A4: 45454.579 | B4: 38.030953 | C4: =+Sheet1!H5 -> 45454.717 | D4: =+C4-2/24 -> 45454.634 | E4: {=INDEX(B$1:B$224233, MATCH(D4,A$1:A$224233,1) +0)} -> 55.889996
A5: 45454.58 | B5: 38.595207 | C5: =+Sheet1!H6 -> 45454.728 | D5: =+C5-2/24 -> 45454.644 | E5: {=INDEX(B$1:B$224233, MATCH(D5,A$1:A$224233,1) +0)} -> 57.38251
A6: 45454.581 | B6: 39.23668 | C6: =+Sheet1!H7 -> 45454.738 | D6: =+C6-2/24 -> 45454.655 | E6: {=INDEX(B$1:B$224233, MATCH(D6,A$1:A$224233,1) +0)} -> 58.622751
A7: 45454.581 | B7: 39.312239 | C7: =+Sheet1!H8 -> 45454.748 | D7: =+C7-2/24 -> 45454.665 | E7: {=INDEX(B$1:B$224233, MATCH(D7,A$1:A$224233,1) +0)} -> 59.364278
A8: 45454.582 | B8: 40.180566 | C8: =+Sheet1!H9 -> 45454.759 | D8: =+C8-2/24 -> 45454.676 | E8: {=INDEX(B$1:B$224233, MATCH(D8,A$1:A$224233,1) +0)} -> 60.49688
A9: 45454.583 | B9: 40.836531 | C9: =+Sheet1!H10 -> 45454.769 | D9: =+C9-2/24 -> 45454.686 | E9: {=INDEX(B$1:B$224233, MATCH(D9,A$1:A$224233,1) +0)} -> 60.701958
A10: 45454.583 | B10: 41.224652 | C10: =+Sheet1!H11 -> 45454.78 | D10: =+C10-2/24 -> 45454.696 | E10: {=INDEX(B$1:B$224233, MATCH(D10,A$1:A$224233,1) +0)} -> 61.602868
A11: 45454.584 | B11: 41.170332 | C11: =+Sheet1!H12 -> 45454.79 | D11: =+C11-2/24 -> 45454.707 | E11: {=INDEX(B$1:B$224233, MATCH(D11,A$1:A$224233,1) +0)} -> 61.252184
A12: 45454.585 | B12: 42.052441 | C12: =+Sheet1!H13 -> 45454.801 | D12: =+C12-2/24 -> 45454.717 | E12: {=INDEX(B$1:B$224233, MATCH(D12,A$1:A$224233,1) +0)} -> 61.94961
A13: 45454.585 | B13: 42.504838 | C13: =+Sheet1!H14 -> 45454.811 | D13: =+C13-2/24 -> 45454.728 | E13: {=INDEX(B$1:B$224233, MATCH(D13,A$1:A$224233,1) +0)} -> 61.539819
... A62: 45454.619 | B62: 53.872841 | C62: =+Sheet1!H63 -> 45455.322 | D62: =+C62-2/24 -> 45455.238 | E62: {=INDEX(B$1:B$224233, MATCH(D62,A$1:A$224233,1) +0)} -> 60.485227
A63: 45454.62 | B63: 54.186635
A64: 45454.621 | B64: 54.632678
A65: 45454.622 | B65: 54.380645
A66: 45454.622 | B66: 54.737563
A67: 45454.623 | B67: 55.012857
A68: 45454.624 | B68: 54.477944
A69: 45454.624 | B69: 55.723485
A70: 45454.625 | B70: 56.230029
A71: 45454.626 | B71: 55.667938
A72: 45454.626 | B72: 56.547567
A73: 45454.627 | B73: 56.344514
A74: 45454.628 | B74: 56.187538
... A1195: 45455.406 | B1195: 11.286162
