Workbook

Sheet Acidic catholyte_Cs2SO4
A1: Electrode | B1: Inlet flow rate | C1: Flow rate (ml min-1) | D1: Catholyte | E1: Anolyte | F1: Membrane | G1: Applied current / A | H1: Time | I1: Duration / h | J1: area(H2) | K1: area(CO) | L1: area(CO2) | M1: area(CH4) | N1: area(O2) | O1: area(N2) | P1: c(H2) | Q1: c(CO) | R1: c(CO2) | S1: c(O2) | T1: FE(H2) | U1: FE(CO) | V1: FE(CH4) | W1: Total FE | X1: Carbon efficiency
A2: Ag60 GDE in PTFE holder | B2: 60 | C2: =+'Flow rate'!E1 -> 56.151374 | D2: 0.3 M Na2SO4 | E2: 0.05 M H2SO4 | F2: CCM-CEM | G2: 0 | H2: 45408.585 | I2: 0 | J2: 0 | K2: 0 | L2: 0 | N2: 0 | O2: 0 | P2: =+J2/100 -> 0 | Q2: =+K2/100 -> 0 | R2: =+L2/100 -> 0 | S2: =+AD2/100 -> 0 | T2: 0 | U2: 0 | W2: =+T2+U2 -> 0 | X2: 0
A3: Ag60 GDE in PTFE holder | B3: 60 | C3: =+'Flow rate'!E2 -> 55.082611 | D3: 0.3 M Na2SO4 | E3: 0.05 M H2SO4 | F3: CCM-CEM | G3: -0.124 | H3: 45408.591 | I3: =+(H3-H$2)*24 -> 0.15 | J3: 0.122692 | K3: 0.87906504 | L3: 100.52735 | N3: 0.095383866 | O3: 0.21200767 | P3: =+J3/SUM($J3:$O3) -> 0.001204794 | Q3: =+K3/SUM($J3:$O3) -> 0.0086321217 | R3: =+L3/SUM($J3:$O3) -> 0.9871446 | S3: =+N3/SUM($J3:$O3) -> 0.00093663734 | T3: =+P3*C3/1000/60/24.3*2*96485/-1/G3 -> 0.070833367 | U3: =+Q3*C3/1000/60/24.3*2*96485/-1/G3 -> 0.50750773 | W3: =+T3+U3 -> 0.5783411 | X3: =+K3/(K3+L3) -> 0.0086687322 | Y3: =+SUM(J3:L3) -> 101.52911
A4: Ag60 GDE in PTFE holder | B4: 60 | C4: =+'Flow rate'!E3 -> 57.183324 | D4: 0.3 M Na2SO4 | E4: 0.05 M H2SO4 | F4: CCM-CEM | G4: -0.124 | H4: 45408.608 | I4: =+(H4-H$2)*24 -> 0.56666667 | J4: 0.16651957 | K4: 1.4971956 | L4: 99.740162 | N4: 0.070937424 | O4: 0.15299291 | P4: =+J4/SUM($J4:$O4) -> 0.0016385237 | Q4: =+K4/SUM($J4:$O4) -> 0.014732145 | R4: =+L4/SUM($J4:$O4) -> 0.9814259 | S4: =+N4/SUM($J4:$O4) -> 0.00069801195 | T4: =+P4*C4/1000/60/24.3*2*96485/-1/G4 -> 0.10000753 | U4: =+Q4*C4/1000/60/24.3*2*96485/-1/G4 -> 0.89917864 | W4: =+T4+U4 -> 0.99918617 | X4: =+K4/(K4+L4) -> 0.014788964
A5: Ag60 GDE in PTFE holder | B5: 60 | C5: =+'Flow rate'!E4 -> 58.115887 | D5: 0.3 M Na2SO4 | E5: 0.05 M H2SO4 | F5: CCM-CEM | G5: -0.124 | H5: 45408.626 | I5: =+(H5-H$2)*24 -> 1 | J5: 0.17721207 | K5: 1.5047509 | L5: 99.64181 | N5: 0.057896134 | O5: 0.12504 | P5: =+J5/SUM($J5:$O5) -> 0.0017458163 | Q5: =+K5/SUM($J5:$O5) -> 0.014824153 | R5: =+L5/SUM($J5:$O5) -> 0.98162782 | S5: =+N5/SUM($J5:$O5) -> 0.00057036756 | T5: =+P5*C5/1000/60/24.3*2*96485/-1/G5 -> 0.1082939 | U5: =+Q5*C5/1000/60/24.3*2*96485/-1/G5 -> 0.91954998 | W5: =+T5+U5 -> 1.0278439 | X5: =+K5/(K5+L5) -> 0.014876936 | Y5: =+SUM(J5:L5) -> 101.32377
A6: Ag60 GDE in PTFE holder | B6: 60 | C6: =+'Flow rate'!E5 -> 58.045685 | D6: 0.3 M Na2SO4 | E6: 0.05 M H2SO4 | F6: CCM-CEM | G6: -0.124 | H6: 45408.644 | I6: =+(H6-H$2)*24 -> 1.4166667 | J6: 0.18322375 | K6: 1.4635366 | L6: 99.738351 | N6: 0.050546182 | O6: 0.11022847 | P6: =+J6/SUM($J6:$O6) -> 0.0018043443 | Q6: =+K6/SUM($J6:$O6) -> 0.014412564 | R6: =+L6/SUM($J6:$O6) -> 0.98219982 | S6: =+N6/SUM($J6:$O6) -> 0.00049776691 | T6: =+P6*C6/1000/60/24.3*2*96485/-1/G6 -> 0.11178923 | U6: =+Q6*C6/1000/60/24.3*2*96485/-1/G6 -> 0.89293897 | W6: =+T6+U6 -> 1.0047282 | X6: =+K6/(K6+L6) -> 0.014461554
A7: Ag60 GDE in PTFE holder | B7: 60 | C7: =+'Flow rate'!E6 -> 58.903171 | D7: 0.3 M Na2SO4 | E7: 0.05 M H2SO4 | F7: CCM-CEM | G7: -0.124 | H7: 45408.662 | I7: =+(H7-H$2)*24 -> 1.85 | J7: 0.18601271 | K7: 1.4357084 | L7: 99.810069 | N7: 0.04342794 | O7: 0.089881266 | P7: =+J7/SUM($J7:$O7) -> 0.0018314629 | Q7: =+K7/SUM($J7:$O7) -> 0.014135844 | R7: =+L7/SUM($J7:$O7) -> 0.98272014 | S7: =+N7/SUM($J7:$O7) -> 0.00042758723 | T7: =+P7*C7/1000/60/24.3*2*96485/-1/G7 -> 0.11514561 | U7: =+Q7*C7/1000/60/24.3*2*96485/-1/G7 -> 0.8887324 | W7: =+T7+U7 -> 1.003878 | X7: =+K7/(K7+L7) -> 0.014180428 | Y7: =+SUM(J7:L7) -> 101.43179
A8: Ag60 GDE in PTFE holder | B8: 60 | C8: =+'Flow rate'!E7 -> 58.602159 | D8: 0.3 M Na2SO4 | E8: 0.05 M H2SO4 | F8: CCM-CEM | G8: -0.27 | H8: 45408.679 | I8: =+(H8-H$2)*24 -> 2.2666667 | J8: 0.67223923 | K8: 2.6302013 | L8: 98.419341 | N8: 0.039449018 | O8: 0.07957343 | P8: =+J8/SUM($J8:$O8) -> 0.006600883 | Q8: =+K8/SUM($J8:$O8) -> 0.025826596 | R8: =+L8/SUM($J8:$O8) -> 0.96640381 | S8: =+N8/SUM($J8:$O8) -> 0.00038735965 | T8: =+P8*C8/1000/60/24.3*2*96485/-1/G8 -> 0.18962001 | U8: =+Q8*C8/1000/60/24.3*2*96485/-1/G8 -> 0.74190671 | W8: =+T8+U8 -> 0.93152671 | X8: =+K8/(K8+L8) -> 0.02602883
A9: Ag60 GDE in PTFE holder | B9: 60 | C9: =+'Flow rate'!E8 -> 58.569921 | D9: 0.3 M Na2SO4 | E9: 0.05 M H2SO4 | F9: CCM-CEM | G9: -0.27 | H9: 45408.697 | I9: =+(H9-H$2)*24 -> 2.7 | J9: 0.57202911 | K9: 2.8127207 | L9: 98.161719 | N9: 0.032456871 | O9: 0.053495348 | P9: =+J9/SUM($J9:$O9) -> 0.0056284117 | Q9: =+K9/SUM($J9:$O9) -> 0.027675427 | R9: =+L9/SUM($J9:$O9) -> 0.96585044 | S9: =+N9/SUM($J9:$O9) -> 0.00031935549 | T9: =+P9*C9/1000/60/24.3*2*96485/-1/G9 -> 0.16159541 | U9: =+Q9*C9/1000/60/24.3*2*96485/-1/G9 -> 0.79457972 | W9: =+T9+U9 -> 0.95617513 | X9: =+K9/(K9+L9) -> 0.027855769 | Y9: =+SUM(J9:L9) -> 101.54647
A10: Ag60 GDE in PTFE holder | B10: 60 | C10: =+'Flow rate'!E9 -> 58.313673 | D10: 0.3 M Na2SO4 | E10: 0.05 M H2SO4 | F10: CCM-CEM | G10: -0.27 | H10: 45408.715 | I10: =+(H10-H$2)*24 -> 3.1166667 | J10: 0.5879591 | K10: 2.8312488 | L10: 98.174443 | N10: 0.031006277 | O10: 0.049395409 | P10: =+J10/SUM($J10:$O10) -> 0.0057827841 | Q10: =+K10/SUM($J10:$O10) -> 0.027846326 | R10: =+L10/SUM($J10:$O10) -> 0.96558011 | S10: =+N10/SUM($J10:$O10) -> 0.00030495762 | T10: =+P10*C10/1000/60/24.3*2*96485/-1/G10 -> 0.16530115 | U10: =+Q10*C10/1000/60/24.3*2*96485/-1/G10 -> 0.79598853 | W10: =+T10+U10 -> 0.96128968 | X10: =+K10/(K10+L10) -> 0.028030587
A11: Ag60 GDE in PTFE holder | B11: 60 | C11: =+'Flow rate'!E10 -> 59.759113 | D11: 0.3 M Na2SO4 | E11: 0.05 M H2SO4 | F11: CCM-CEM | G11: -0.27 | H11: 45408.733 | I11: =+(H11-H$2)*24 -> 3.55 | J11: 0.56502258 | K11: 2.7202591 | L11: 98.077553 | N11: 0.032021682 | O11: 0.054648452 | P11: =+J11/SUM($J11:$O11) -> 0.0055694957 | Q11: =+K11/SUM($J11:$O11) -> 0.026813922 | R11: =+L11/SUM($J11:$O11) -> 0.96676226 | S11: =+N11/SUM($J11:$O11) -> 0.00031564158 | T11: =+P11*C11/1000/60/24.3*2*96485/-1/G11 -> 0.16315054 | U11: =+Q11*C11/1000/60/24.3*2*96485/-1/G11 -> 0.78547612 | W11: =+T11+U11 -> 0.94862667 | X11: =+K11/(K11+L11) -> 0.026987283 | Y11: =+SUM(J11:L11) -> 101.36283
A12: Ag60 GDE in PTFE holder | B12: 60 | C12: =+'Flow rate'!E11 -> 59.335781 | D12: 0.3 M Na2SO4 | E12: 0.05 M H2SO4 | F12: CCM-CEM | G12: -0.27 | H12: 45408.75 | I12: =+(H12-H$2)*24 -> 3.9666667 | J12: 0.57483177 | K12: 2.8333412 | L12: 98.263297 | N12: 0.031977731 | O12: 0.057874288 | P12: =+J12/SUM($J12:$O12) -> 0.0056488237 | Q12: =+K12/SUM($J12:$O12) -> 0.027843007 | R12: =+L12/SUM($J12:$O12) -> 0.9656252 | S12: =+N12/SUM($J12:$O12) -> 0.00031424249 | T12: =+P12*C12/1000/60/24.3*2*96485/-1/G12 -> 0.16430213 | U12: =+Q12*C12/1000/60/24.3*2*96485/-1/G12 -> 0.8098439 | W12: =+T12+U12 -> 0.97414603 | X12: =+K12/(K12+L12) -> 0.028026068
A13: Ag60 GDE in PTFE holder | B13: 60 | C13: =+'Flow rate'!E12 -> 60.443483 | D13: 0.3 M Na2SO4 | E13: 0.05 M H2SO4 | F13: CCM-CEM | G13: -0.52 | H13: 45408.768 | I13: =+(H13-H$2)*24 -> 4.4 | J13: 0.84790145 | K13: 5.0359289 | L13: 95.197769 | N13: 0.03188518 | O13: 0.050033578 | P13: =+J13/SUM($J13:$O13) -> 0.0083814944 | Q13: =+K13/SUM($J13:$O13) -> 0.049780088 | R13: =+L13/SUM($J13:$O13) -> 0.94102865 | S13: =+N13/SUM($J13:$O13) -> 0.00031518457 | T13: =+P13*C13/1000/60/24.3*2*96485/-1/G13 -> 0.12894362 | U13: =+Q13*C13/1000/60/24.3*2*96485/-1/G13 -> 0.765833 | W13: =+T13+U13 -> 0.89477662 | X13: =+K13/(K13+L13) -> 0.050241875 | Y13: =+SUM(J13:L13) -> 101.0816
A14: Ag60 GDE in PTFE holder | B14: 60 | C14: =+'Flow rate'!E13 -> 60.575346 | D14: 0.3 M Na2SO4 | E14: 0.05 M H2SO4 | F14: CCM-CEM | G14: -0.52 | H14: 45408.785 | I14: =+(H14-H$2)*24 -> 4.8166667 | J14: 0.83145185 | K14: 5.2392839 | L14: 94.999932 | N14: 0.030877968 | O14: 0.046373089 | P14: =+J14/SUM($J14:$O14) -> 0.0082201578 | Q14: =+K14/SUM($J14:$O14) -> 0.051798237 | R14: =+L14/SUM($J14:$O14) -> 0.93921786 | S14: =+N14/SUM($J14:$O14) -> 0.00030527536 | T14: =+P14*C14/1000/60/24.3*2*96485/-1/G14 -> 0.12673746 | U14: =+Q14*C14/1000/60/24.3*2*96485/-1/G14 -> 0.79861932 | W14: =+T14+U14 -> 0.92535677 | X14: =+K14/(K14+L14) -> 0.052267806
A15: Ag60 GDE in PTFE holder | B15: 60 | C15: =+'Flow rate'!E14 -> 61.293408 | D15: 0.3 M Na2SO4 | E15: 0.05 M H2SO4 | F15: CCM-CEM | G15: -0.52 | H15: 45408.803 | I15: =+(H15-H$2)*24 -> 5.25 | J15: 0.83245105 | K15: 5.2938813 | L15: 94.931053 | N15: 0.029318327 | O15: 0.041714446 | P15: =+J15/SUM($J15:$O15) -> 0.0082316233 | Q15: =+K15/SUM($J15:$O15) -> 0.052348108 | R15: =+L15/SUM($J15:$O15) -> 0.93871787 | S15: =+N15/SUM($J15:$O15) -> 0.00028991185 | T15: =+P15*C15/1000/60/24.3*2*96485/-1/G15 -> 0.12841868 | U15: =+Q15*C15/1000/60/24.3*2*96485/-1/G15 -> 0.81666451 | W15: =+T15+U15 -> 0.94508319 | X15: =+K15/(K15+L15) -> 0.052820003 | Y15: =+SUM(J15:L15) -> 101.05739
A16: Ag60 GDE in PTFE holder | B16: 60 | C16: =+'Flow rate'!E15 -> 59.99416 | D16: 0.3 M Na2SO4 | E16: 0.05 M H2SO4 | F16: CCM-CEM | G16: -0.52 | H16: 45408.821 | I16: =+(H16-H$2)*24 -> 5.6666667 | J16: 0.63518819 | K16: 5.3015481 | L16: 94.936371 | N16: 0.031755874 | O16: 0.050913883 | P16: =+J16/SUM($J16:$O16) -> 0.0062917468 | Q16: =+K16/SUM($J16:$O16) -> 0.052513568 | R16: =+L16/SUM($J16:$O16) -> 0.94037581 | S16: =+N16/SUM($J16:$O16) -> 0.00031455233 | T16: =+P16*C16/1000/60/24.3*2*96485/-1/G16 -> 0.096074723 | U16: =+Q16*C16/1000/60/24.3*2*96485/-1/G16 -> 0.8018801 | W16: =+T16+U16 -> 0.89795482 | X16: =+K16/(K16+L16) -> 0.052889646
A17: Ag60 GDE in PTFE holder | B17: 60 | C17: =+'Flow rate'!E16 -> 60.571302 | D17: 0.3 M Na2SO4 | E17: 0.05 M H2SO4 | F17: CCM-CEM | G17: -0.77 | H17: 45408.839 | I17: =+(H17-H$2)*24 -> 6.1 | J17: 0.86346229 | K17: 6.086892 | L17: 94.111568 | N17: 0.030378014 | O17: 0.044517333 | P17: =+J17/SUM($J17:$O17) -> 0.0085375663 | Q17: =+K17/SUM($J17:$O17) -> 0.060184729 | R17: =+L17/SUM($J17:$O17) -> 0.93053717 | S17: =+N17/SUM($J17:$O17) -> 0.00030036554 | T17: =+P17*C17/1000/60/24.3*2*96485/-1/G17 -> 0.08888788 | U17: =+Q17*C17/1000/60/24.3*2*96485/-1/G17 -> 0.62660631 | W17: =+T17+U17 -> 0.71549419 | X17: =+K17/(K17+L17) -> 0.060748359 | Y17: =+SUM(J17:L17) -> 101.06192
A18: Ag60 GDE in PTFE holder | B18: 60 | C18: =+'Flow rate'!E17 -> 61.548426 | D18: 0.3 M Na2SO4 | E18: 0.05 M H2SO4 | F18: CCM-CEM | G18: -0.77 | H18: 45408.856 | I18: =+(H18-H$2)*24 -> 6.5166667 | J18: 0.95002593 | K18: 7.4247214 | L18: 92.559688 | N18: 0.032061426 | O18: 0.043372538 | P18: =+J18/SUM($J18:$O18) -> 0.0094052783 | Q18: =+K18/SUM($J18:$O18) -> 0.07350491 | R18: =+L18/SUM($J18:$O18) -> 0.91634301 | S18: =+N18/SUM($J18:$O18) -> 0.00031740884 | T18: =+P18*C18/1000/60/24.3*2*96485/-1/G18 -> 0.099501619 | U18: =+Q18*C18/1000/60/24.3*2*96485/-1/G18 -> 0.7776333 | W18: =+T18+U18 -> 0.87713492 | X18: =+K18/(K18+L18) -> 0.074258791
A19: Ag60 GDE in PTFE holder | B19: 60 | C19: =+'Flow rate'!E18 -> 61.343175 | D19: 0.3 M Na2SO4 | E19: 0.05 M H2SO4 | F19: CCM-CEM | G19: -0.77 | H19: 45408.874 | I19: =+(H19-H$2)*24 -> 6.95 | J19: 0.98961019 | K19: 7.5179597 | L19: 92.433429 | N19: 0.031378142 | O19: 0.039977475 | P19: =+J19/SUM($J19:$O19) -> 0.0097969224 | Q19: =+K19/SUM($J19:$O19) -> 0.074426141 | R19: =+L19/SUM($J19:$O19) -> 0.91507053 | S19: =+N19/SUM($J19:$O19) -> 0.00031063668 | T19: =+P19*C19/1000/60/24.3*2*96485/-1/G19 -> 0.10329932 | U19: =+Q19*C19/1000/60/24.3*2*96485/-1/G19 -> 0.78475357 | W19: =+T19+U19 -> 0.88805289 | X19: =+K19/(K19+L19) -> 0.075216161 | Y19: =+SUM(J19:L19) -> 100.941
A20: Ag60 GDE in PTFE holder | B20: 60 | C20: =+'Flow rate'!E19 -> 61.845123 | D20: 0.3 M Na2SO4 | E20: 0.05 M H2SO4 | F20: CCM-CEM | G20: -0.77 | H20: 45408.893 | I20: =+(H20-H$2)*24 -> 7.4 | J20: 0.99972128 | K20: 7.544491 | L20: 92.373531 | N20: 0.032266123 | O20: 0.045130106 | P20: =+J20/SUM($J20:$O20) -> 0.0098987068 | Q20: =+K20/SUM($J20:$O20) -> 0.074701525 | R20: =+L20/SUM($J20:$O20) -> 0.91463343 | S20: =+N20/SUM($J20:$O20) -> 0.00031948194 | T20: =+P20*C20/1000/60/24.3*2*96485/-1/G20 -> 0.10522658 | U20: =+Q20*C20/1000/60/24.3*2*96485/-1/G20 -> 0.79410233 | W20: =+T20+U20 -> 0.89932892 | X20: =+K20/(K20+L20) -> 0.075506808
A21: Ag60 GDE in PTFE holder | B21: 60 | C21: =+'Flow rate'!E20 -> 61.024411 | D21: 0.3 M Na2SO4 | E21: 0.05 M H2SO4 | F21: CCM-CEM | G21: -0.77 | H21: 45408.905 | I21: =+(H21-H$2)*24 -> 7.6833333 | J21: 0.95336395 | K21: 7.5815556 | L21: 92.341911 | N21: 0.031677383 | O21: 0.041888002 | P21: =+J21/SUM($J21:$O21) -> 0.0094438852 | Q21: =+K21/SUM($J21:$O21) -> 0.075101791 | R21: =+L21/SUM($J21:$O21) -> 0.9147256 | S21: =+N21/SUM($J21:$O21) -> 0.00031379157 | T21: =+P21*C21/1000/60/24.3*2*96485/-1/G21 -> 0.099059434 | U21: =+Q21*C21/1000/60/24.3*2*96485/-1/G21 -> 0.78776275 | W21: =+T21+U21 -> 0.88682218 | X21: =+K21/(K21+L21) -> 0.075873624 | Y21: =+SUM(J21:L21) -> 100.87683
A22: Ag60 GDE in PTFE holder | B22: 60 | C22: =+'Flow rate'!E21 -> 60.666042 | D22: 0.3 M Na2SO4 | E22: 0.05 M H2SO4 | F22: CCM-CEM | G22: -0.77 | H22: 45408.917 | I22: =+(H22-H$2)*24 -> 7.9666667 | J22: 0.84366174 | K22: 7.5531742 | L22: 92.33888 | N22: 0.030749658 | O22: 0.03961585 | P22: =+J22/SUM($J22:$O22) -> 0.0083691552 | Q22: =+K22/SUM($J22:$O22) -> 0.074927764 | R22: =+L22/SUM($J22:$O22) -> 0.91600505 | S22: =+N22/SUM($J22:$O22) -> 0.00030503773 | T22: =+P22*C22/1000/60/24.3*2*96485/-1/G22 -> 0.087270774 | U22: =+Q22*C22/1000/60/24.3*2*96485/-1/G22 -> 0.78132187 | W22: =+T22+U22 -> 0.86859264 | X22: =+K22/(K22+L22) -> 0.075613364
A23: Ag60 GDE in PTFE holder | B23: 60 | C23: =+'Flow rate'!E22 -> 62.499085 | D23: 0.3 M Na2SO4 | E23: 0.05 M H2SO4 | F23: CCM-CEM | G23: -1.1 | H23: 45408.928 | I23: =+(H23-H$2)*24 -> 8.25 | J23: 2.8564526 | K23: 8.7598644 | L23: 90.501276 | N23: 0.032962803 | O23: 0.041501918 | P23: =+J23/SUM($J23:$O23) -> 0.027951806 | Q23: =+K23/SUM($J23:$O23) -> 0.08571962 | R23: =+L23/SUM($J23:$O23) -> 0.8855999 | S23: =+N23/SUM($J23:$O23) -> 0.00032255738 | T23: =+P23*C23/1000/60/24.3*2*96485/-1/G23 -> 0.21019536 | U23: =+Q23*C23/1000/60/24.3*2*96485/-1/G23 -> 0.64460472 | W23: =+T23+U23 -> 0.85480008 | X23: =+K23/(K23+L23) -> 0.088250692 | Y23: =+SUM(J23:L23) -> 102.11759
A24: Ag60 GDE in PTFE holder | B24: 60 | C24: =+'Flow rate'!E23 -> 62.456899 | D24: 0.3 M Na2SO4 | E24: 0.05 M H2SO4 | F24: CCM-CEM | G24: -1.1 | H24: 45408.94 | I24: =+(H24-H$2)*24 -> 8.5333333 | J24: 2.8678677 | K24: 9.0223228 | L24: 90.036769 | N24: 0.03250669 | O24: 0.040378657 | P24: =+J24/SUM($J24:$O24) -> 0.028116393 | Q24: =+K24/SUM($J24:$O24) -> 0.08845428 | R24: =+L24/SUM($J24:$O24) -> 0.88271476 | S24: =+N24/SUM($J24:$O24) -> 0.00031869352 | T24: =+P24*C24/1000/60/24.3*2*96485/-1/G24 -> 0.21129032 | U24: =+Q24*C24/1000/60/24.3*2*96485/-1/G24 -> 0.66472017 | W24: =+T24+U24 -> 0.87601049 | X24: =+K24/(K24+L24) -> 0.09108021
A25: Ag60 GDE in PTFE holder | B25: 60 | C25: =+'Flow rate'!E24 -> 61.365043 | D25: 0.3 M Na2SO4 | E25: 0.05 M H2SO4 | F25: CCM-CEM | G25: -1.1 | H25: 45408.952 | I25: =+(H25-H$2)*24 -> 8.8166667 | J25: 2.9296899 | K25: 9.0299613 | L25: 89.962792 | N25: 0.033137277 | O25: 0.042251149 | P25: =+J25/SUM($J25:$O25) -> 0.02872306 | Q25: =+K25/SUM($J25:$O25) -> 0.088530914 | R25: =+L25/SUM($J25:$O25) -> 0.88200691 | S25: =+N25/SUM($J25:$O25) -> 0.00032488217 | T25: =+P25*C25/1000/60/24.3*2*96485/-1/G25 -> 0.21207591 | U25: =+Q25*C25/1000/60/24.3*2*96485/-1/G25 -> 0.65366553 | W25: =+T25+U25 -> 0.86574143 | X25: =+K25/(K25+L25) -> 0.091218407 | Y25: =+SUM(J25:L25) -> 101.92244
A26: Ag60 GDE in PTFE holder | B26: 60 | C26: =+'Flow rate'!E25 -> 61.664238 | D26: 0.3 M Na2SO4 | E26: 0.05 M H2SO4 | F26: CCM-CEM | G26: -1.1 | H26: 45408.964 | I26: =+(H26-H$2)*24 -> 9.1 | J26: 2.8887577 | K26: 9.0539658 | L26: 89.891289 | N26: 0.032324244 | O26: 0.031602754 | P26: =+J26/SUM($J26:$O26) -> 0.02834952 | Q26: =+K26/SUM($J26:$O26) -> 0.088853276 | R26: =+L26/SUM($J26:$O26) -> 0.88216984 | S26: =+N26/SUM($J26:$O26) -> 0.00031722177 | T26: =+P26*C26/1000/60/24.3*2*96485/-1/G26 -> 0.21033845 | U26: =+Q26*C26/1000/60/24.3*2*96485/-1/G26 -> 0.65924433 | W26: =+T26+U26 -> 0.86958278 | X26: =+K26/(K26+L26) -> 0.0915048
A27: Ag60 GDE in PTFE holder | B27: 60 | C27: =+'Flow rate'!E26 -> 62.305059 | D27: 0.3 M Na2SO4 | E27: 0.05 M H2SO4 | F27: CCM-CEM | G27: -1.1 | H27: 45408.976 | I27: =+(H27-H$2)*24 -> 9.3833333 | J27: 2.9054286 | K27: 9.068755 | L27: 89.88004 | N27: 0.032156855 | O27: 0.040334653 | P27: =+J27/SUM($J27:$O27) -> 0.028505075 | Q27: =+K27/SUM($J27:$O27) -> 0.088973288 | R27: =+L27/SUM($J27:$O27) -> 0.88181042 | S27: =+N27/SUM($J27:$O27) -> 0.00031548996 | T27: =+P27*C27/1000/60/24.3*2*96485/-1/G27 -> 0.21369044 | U27: =+Q27*C27/1000/60/24.3*2*96485/-1/G27 -> 0.66699494 | W27: =+T27+U27 -> 0.88068538 | X27: =+K27/(K27+L27) -> 0.09165099 | Y27: =+SUM(J27:L27) -> 101.85422
A28: Ag60 GDE in PTFE holder | B28: 60 | C28: =+'Flow rate'!E27 -> 61.961997 | D28: 0.3 M Na2SO4 | E28: 0.05 M H2SO4 | F28: CCM-CEM | G28: -1.1 | H28: 45408.988 | I28: =+(H28-H$2)*24 -> 9.6666667 | J28: 2.9628627 | K28: 9.0457977 | L28: 89.825512 | N28: 0.032938226 | O28: 0.043617834 | P28: =+J28/SUM($J28:$O28) -> 0.029073119 | Q28: =+K28/SUM($J28:$O28) -> 0.088761976 | R28: =+L28/SUM($J28:$O28) -> 0.8814137 | S28: =+N28/SUM($J28:$O28) -> 0.00032320665 | T28: =+P28*C28/1000/60/24.3*2*96485/-1/G28 -> 0.21674876 | U28: =+Q28*C28/1000/60/24.3*2*96485/-1/G28 -> 0.66174696 | W28: =+T28+U28 -> 0.87849572 | X28: =+K28/(K28+L28) -> 0.091490622
A29: Ag60 GDE in PTFE holder | B29: 60 | C29: =+'Flow rate'!E28 -> 61.866269 | D29: 0.3 M Na2SO4 | E29: 0.05 M H2SO4 | F29: CCM-CEM | G29: -1.52 | H29: 45408.999 | I29: =+(H29-H$2)*24 -> 9.95 | J29: 3.2177891 | K29: 9.9469348 | L29: 89.831449 | N29: 0.031681036 | O29: 0.031912885 | P29: =+J29/SUM($J29:$O29) -> 0.031222554 | Q29: =+K29/SUM($J29:$O29) -> 0.096516178 | R29: =+L29/SUM($J29:$O29) -> 0.87164421 | S29: =+N29/SUM($J29:$O29) -> 0.0003074045 | T29: =+P29*C29/1000/60/24.3*2*96485/-1/G29 -> 0.16819421 | U29: =+Q29*C29/1000/60/24.3*2*96485/-1/G29 -> 0.51992742 | W29: =+T29+U29 -> 0.68812163 | X29: =+K29/(K29+L29) -> 0.099690278 | Y29: =+SUM(J29:L29) -> 102.99617
A30: Ag60 GDE in PTFE holder | B30: 60 | C30: =+'Flow rate'!E29 -> 64.618812 | D30: 0.3 M Na2SO4 | E30: 0.05 M H2SO4 | F30: CCM-CEM | G30: -1.52 | H30: 45409.011 | I30: =+(H30-H$2)*24 -> 10.233333 | J30: 4.8993599 | K30: 10.887568 | L30: 86.310397 | N30: 0.033328136 | O30: 0.040573396 | P30: =+J30/SUM($J30:$O30) -> 0.047952443 | Q30: =+K30/SUM($J30:$O30) -> 0.10656198 | R30: =+L30/SUM($J30:$O30) -> 0.84476227 | S30: =+N30/SUM($J30:$O30) -> 0.00032619884 | T30: =+P30*C30/1000/60/24.3*2*96485/-1/G30 -> 0.26981022 | U30: =+Q30*C30/1000/60/24.3*2*96485/-1/G30 -> 0.59958387 | W30: =+T30+U30 -> 0.86939408 | X30: =+K30/(K30+L30) -> 0.11201436
A31: Ag60 GDE in PTFE holder | B31: 60 | C31: =+'Flow rate'!E30 -> 64.136691 | D31: 0.3 M Na2SO4 | E31: 0.05 M H2SO4 | F31: CCM-CEM | G31: -1.52 | H31: 45409.023 | I31: =+(H31-H$2)*24 -> 10.516667 | J31: 5.6829116 | K31: 11.094536 | L31: 85.437438 | N31: 0.033143255 | O31: 0.03905422 | P31: =+J31/SUM($J31:$O31) -> 0.055558448 | Q31: =+K31/SUM($J31:$O31) -> 0.10846469 | R31: =+L31/SUM($J31:$O31) -> 0.83527103 | S31: =+N31/SUM($J31:$O31) -> 0.0003240219 | T31: =+P31*C31/1000/60/24.3*2*96485/-1/G31 -> 0.31027397 | U31: =+Q31*C31/1000/60/24.3*2*96485/-1/G31 -> 0.6057363 | W31: =+T31+U31 -> 0.91601027 | X31: =+K31/(K31+L31) -> 0.11493121 | Y31: =+SUM(J31:L31) -> 102.21489
A32: Ag60 GDE in PTFE holder | B32: 60 | C32: =+'Flow rate'!E31 -> 65.196413 | D32: 0.3 M Na2SO4 | E32: 0.05 M H2SO4 | F32: CCM-CEM | G32: -1.52 | H32: 45409.035 | I32: =+(H32-H$2)*24 -> 10.8 | J32: 5.8481244 | K32: 11.122325 | L32: 85.292806 | N32: 0.032836154 | O32: 0.039267333 | P32: =+J32/SUM($J32:$O32) -> 0.057146664 | Q32: =+K32/SUM($J32:$O32) -> 0.10868507 | R32: =+L32/SUM($J32:$O32) -> 0.83346369 | S32: =+N32/SUM($J32:$O32) -> 0.00032086811 | T32: =+P32*C32/1000/60/24.3*2*96485/-1/G32 -> 0.32441675 | U32: =+Q32*C32/1000/60/24.3*2*96485/-1/G32 -> 0.61699587 | W32: =+T32+U32 -> 0.94141262 | X32: =+K32/(K32+L32) -> 0.11535871
A33: Ag60 GDE in PTFE holder | B33: 60 | C33: =+'Flow rate'!E32 -> 64.401972 | D33: 0.3 M Na2SO4 | E33: 0.05 M H2SO4 | F33: CCM-CEM | G33: -1.52 | H33: 45409.047 | I33: =+(H33-H$2)*24 -> 11.083333 | J33: 5.8101087 | K33: 11.023506 | L33: 85.183949 | N33: 0.033028563 | O33: 0.038679838 | P33: =+J33/SUM($J33:$O33) -> 0.05691204 | Q33: =+K33/SUM($J33:$O33) -> 0.10797908 | R33: =+L33/SUM($J33:$O33) -> 0.83440647 | S33: =+N33/SUM($J33:$O33) -> 0.00032352628 | T33: =+P33*C33/1000/60/24.3*2*96485/-1/G33 -> 0.31914791 | U33: =+Q33*C33/1000/60/24.3*2*96485/-1/G33 -> 0.60551859 | W33: =+T33+U33 -> 0.9246665 | X33: =+K33/(K33+L33) -> 0.11458058 | Y33: =+SUM(J33:L33) -> 102.01756
A34: Ag60 GDE in PTFE holder | B34: 60 | C34: =+'Flow rate'!E33 -> 64.285295 | D34: 0.3 M Na2SO4 | E34: 0.05 M H2SO4 | F34: CCM-CEM | G34: -1.52 | H34: 45409.058 | I34: =+(H34-H$2)*24 -> 11.366667 | J34: 5.7932428 | K34: 11.010941 | L34: 85.127102 | N34: 0.033365334 | O34: 0.040108082 | P34: =+J34/SUM($J34:$O34) -> 0.056793848 | Q34: =+K34/SUM($J34:$O34) -> 0.10794537 | R34: =+L34/SUM($J34:$O34) -> 0.83454049 | S34: =+N34/SUM($J34:$O34) -> 0.00032709585 | T34: =+P34*C34/1000/60/24.3*2*96485/-1/G34 -> 0.31790812 | U34: =+Q34*C34/1000/60/24.3*2*96485/-1/G34 -> 0.60423286 | W34: =+T34+U34 -> 0.92214098 | X34: =+K34/(K34+L34) -> 0.11453261
A35: Ag60 GDE in PTFE holder | B35: 60 | C35: =+'Flow rate'!E34 -> 65.025601 | D35: 0.3 M Na2SO4 | E35: 0.05 M H2SO4 | F35: CCM-CEM | G35: -1.52 | H35: 45409.07 | I35: =+(H35-H$2)*24 -> 11.65 | J35: 5.8786179 | K35: 10.968263 | L35: 85.035694 | N35: 0.032883536 | O35: 0.038319149 | P35: =+J35/SUM($J35:$O35) -> 0.057659638 | Q35: =+K35/SUM($J35:$O35) -> 0.10758074 | R35: =+L35/SUM($J35:$O35) -> 0.83406124 | S35: =+N35/SUM($J35:$O35) -> 0.00032253377 | T35: =+P35*C35/1000/60/24.3*2*96485/-1/G35 -> 0.32647127 | U35: =+Q35*C35/1000/60/24.3*2*96485/-1/G35 -> 0.60912662 | W35: =+T35+U35 -> 0.93559789 | X35: =+K35/(K35+L35) -> 0.11424803 | Y35: =+SUM(J35:L35) -> 101.88257
A36: Ag60 GDE in PTFE holder | B36: 60 | C36: =+'Flow rate'!E35 -> 69.019284 | D36: 0.3 M Na2SO4 | E36: 0.05 M H2SO4 | F36: CCM-CEM | G36: -2.1 | H36: 45409.09 | I36: =+(H36-H$2)*24 -> 12.116667 | J36: 7.8511893 | K36: 11.004753 | L36: 83.097119 | N36: 0.033136834 | O36: 0.036972008 | P36: =+J36/SUM($J36:$O36) -> 0.076954963 | Q36: =+K36/SUM($J36:$O36) -> 0.10786524 | R36: =+L36/SUM($J36:$O36) -> 0.81449261 | S36: =+N36/SUM($J36:$O36) -> 0.00032479714 | T36: =+P36*C36/1000/60/24.3*2*96485/-1/G36 -> 0.33474959 | U36: =+Q36*C36/1000/60/24.3*2*96485/-1/G36 -> 0.46920749 | W36: =+T36+U36 -> 0.80395708 | X36: =+K36/(K36+L36) -> 0.11694511
A37: Ag60 GDE in PTFE holder | B37: 60 | C37: =+'Flow rate'!E36 -> 68.872149 | D37: 0.3 M Na2SO4 | E37: 0.05 M H2SO4 | F37: CCM-CEM | G37: -2.1 | H37: 45409.101 | I37: =+(H37-H$2)*24 -> 12.4 | J37: 9.8994322 | K37: 10.969064 | L37: 81.088358 | N37: 0.03978435 | O37: 0.061242784 | P37: =+J37/SUM($J37:$O37) -> 0.096998214 | Q37: =+K37/SUM($J37:$O37) -> 0.10747885 | R37: =+L37/SUM($J37:$O37) -> 0.79453304 | S37: =+N37/SUM($J37:$O37) -> 0.00038982144 | T37: =+P37*C37/1000/60/24.3*2*96485/-1/G37 -> 0.42103709 | U37: =+Q37*C37/1000/60/24.3*2*96485/-1/G37 -> 0.46653005 | W37: =+T37+U37 -> 0.88756714 | X37: =+K37/(K37+L37) -> 0.11915458 | Y37: =+SUM(J37:L37) -> 101.95685
A38: Ag60 GDE in PTFE holder | B38: 60 | C38: =+'Flow rate'!E37 -> 67.477881 | D38: 0.3 M Na2SO4 | E38: 0.05 M H2SO4 | F38: CCM-CEM | G38: -2.1 | H38: 45409.113 | I38: =+(H38-H$2)*24 -> 12.683333 | J38: 10.233072 | K38: 10.892867 | L38: 80.821819 | N38: 0.033755022 | O38: 0.038293403 | P38: =+J38/SUM($J38:$O38) -> 0.10030476 | Q38: =+K38/SUM($J38:$O38) -> 0.10677208 | R38: =+L38/SUM($J38:$O38) -> 0.79221694 | S38: =+N38/SUM($J38:$O38) -> 0.00033086734 | T38: =+P38*C38/1000/60/24.3*2*96485/-1/G38 -> 0.42657556 | U38: =+Q38*C38/1000/60/24.3*2*96485/-1/G38 -> 0.45407973 | W38: =+T38+U38 -> 0.88065529 | X38: =+K38/(K38+L38) -> 0.11876906
A39: Ag60 GDE in PTFE holder | B39: 60 | C39: =+'Flow rate'!E38 -> 67.786168 | D39: 0.3 M Na2SO4 | E39: 0.05 M H2SO4 | F39: CCM-CEM | G39: -2.1 | H39: 45409.138 | I39: =+(H39-H$2)*24 -> 13.283333 | J39: 10.52656 | K39: 10.80432 | L39: 80.625297 | N39: 0.03345246 | O39: 0.037476177 | P39: =+J39/SUM($J39:$O39) -> 0.10317416 | Q39: =+K39/SUM($J39:$O39) -> 0.10589656 | R39: =+L39/SUM($J39:$O39) -> 0.79023409 | S39: =+N39/SUM($J39:$O39) -> 0.00032787816 | T39: =+P39*C39/1000/60/24.3*2*96485/-1/G39 -> 0.44078315 | U39: =+Q39*C39/1000/60/24.3*2*96485/-1/G39 -> 0.45241389 | W39: =+T39+U39 -> 0.89319704 | X39: =+K39/(K39+L39) -> 0.1181709 | Y39: =+SUM(J39:L39) -> 101.95618
A40: Ag60 GDE in PTFE holder | B40: 60 | C40: =+'Flow rate'!E39 -> 67.263091 | D40: 0.3 M Na2SO4 | E40: 0.05 M H2SO4 | F40: CCM-CEM | G40: -2.1 | H40: 45409.15 | I40: =+(H40-H$2)*24 -> 13.566667 | J40: 10.646606 | K40: 10.707494 | L40: 80.59198 | N40: 0.040034215 | O40: 0.061883294 | P40: =+J40/SUM($J40:$O40) -> 0.1043294 | Q40: =+K40/SUM($J40:$O40) -> 0.10492605 | R40: =+L40/SUM($J40:$O40) -> 0.78974583 | S40: =+N40/SUM($J40:$O40) -> 0.0003923077 | T40: =+P40*C40/1000/60/24.3*2*96485/-1/G40 -> 0.44227918 | U40: =+Q40*C40/1000/60/24.3*2*96485/-1/G40 -> 0.44480856 | W40: =+T40+U40 -> 0.88708775 | X40: =+K40/(K40+L40) -> 0.11727881
...

Sheet Flow rate
B1: 0.6Mna2so4ph3 | C1: =+'Acidic catholyte_Cs2SO4'!H2 -> 45408.585 | D1: =+C1-2/24 -> 45408.501 | E1: {=INDEX(B$1:B$224233, MATCH(D1,A$1:A$224233,1) +0)} -> 56.151374
A2: 45408.44 | B2: 0 | C2: =+'Acidic catholyte_Cs2SO4'!H3 -> 45408.591 | D2: =+C2-2/24 -> 45408.508 | E2: {=INDEX(B$1:B$224233, MATCH(D2,A$1:A$224233,1) +0)} -> 55.082611
A3: 45408.44 | B3: 0 | C3: =+'Acidic catholyte_Cs2SO4'!H4 -> 45408.608 | D3: =+C3-2/24 -> 45408.525 | E3: {=INDEX(B$1:B$224233, MATCH(D3,A$1:A$224233,1) +0)} -> 57.183324
A4: 45408.441 | B4: 56.939609 | C4: =+'Acidic catholyte_Cs2SO4'!H5 -> 45408.626 | D4: =+C4-2/24 -> 45408.543 | E4: {=INDEX(B$1:B$224233, MATCH(D4,A$1:A$224233,1) +0)} -> 58.115887
A5: 45408.442 | B5: 48.095144 | C5: =+'Acidic catholyte_Cs2SO4'!H6 -> 45408.644 | D5: =+C5-2/24 -> 45408.56 | E5: {=INDEX(B$1:B$224233, MATCH(D5,A$1:A$224233,1) +0)} -> 58.045685
A6: 45408.442 | B6: 48.236306 | C6: =+'Acidic catholyte_Cs2SO4'!H7 -> 45408.662 | D6: =+C6-2/24 -> 45408.578 | E6: {=INDEX(B$1:B$224233, MATCH(D6,A$1:A$224233,1) +0)} -> 58.903171
A7: 45408.443 | B7: 48.080766 | C7: =+'Acidic catholyte_Cs2SO4'!H8 -> 45408.679 | D7: =+C7-2/24 -> 45408.596 | E7: {=INDEX(B$1:B$224233, MATCH(D7,A$1:A$224233,1) +0)} -> 58.602159
A8: 45408.444 | B8: 47.987889 | C8: =+'Acidic catholyte_Cs2SO4'!H9 -> 45408.697 | D8: =+C8-2/24 -> 45408.614 | E8: {=INDEX(B$1:B$224233, MATCH(D8,A$1:A$224233,1) +0)} -> 58.569921
A9: 45408.444 | B9: 47.180721 | C9: =+'Acidic catholyte_Cs2SO4'!H10 -> 45408.715 | D9: =+C9-2/24 -> 45408.631 | E9: {=INDEX(B$1:B$224233, MATCH(D9,A$1:A$224233,1) +0)} -> 58.313673
A10: 45408.445 | B10: 46.90771 | C10: =+'Acidic catholyte_Cs2SO4'!H11 -> 45408.733 | D10: =+C10-2/24 -> 45408.649 | E10: {=INDEX(B$1:B$224233, MATCH(D10,A$1:A$224233,1) +0)} -> 59.759113
A11: 45408.446 | B11: 47.185285 | C11: =+'Acidic catholyte_Cs2SO4'!H12 -> 45408.75 | D11: =+C11-2/24 -> 45408.667 | E11: {=INDEX(B$1:B$224233, MATCH(D11,A$1:A$224233,1) +0)} -> 59.335781
A12: 45408.447 | B12: 47.248538 | C12: =+'Acidic catholyte_Cs2SO4'!H13 -> 45408.768 | D12: =+C12-2/24 -> 45408.685 | E12: {=INDEX(B$1:B$224233, MATCH(D12,A$1:A$224233,1) +0)} -> 60.443483
A13: 45408.447 | B13: 47.035211 | C13: =+'Acidic catholyte_Cs2SO4'!H14 -> 45408.785 | D13: =+C13-2/24 -> 45408.702 | E13: {=INDEX(B$1:B$224233, MATCH(D13,A$1:A$224233,1) +0)} -> 60.575346
... A119: 45408.521 | B119: 57.415127 | C119: =+'Acidic catholyte_Cs2SO4'!H120 -> 45411.417 | D119: =+C119-2/24 -> 45411.333 | E119: {=INDEX(B$1:B$224233, MATCH(D119,A$1:A$224233,1) +0)} -> 6.786569
A120: 45408.522 | B120: 57.805289
A121: 45408.522 | B121: 57.334504
A122: 45408.523 | B122: 57.81018
A123: 45408.524 | B123: 56.680865
A124: 45408.524 | B124: 57.183324
A125: 45408.525 | B125: 56.83307
A126: 45408.526 | B126: 56.517297
A127: 45408.526 | B127: 55.862331
A128: 45408.527 | B128: 58.119754
A129: 45408.528 | B129: 57.456195
A130: 45408.528 | B130: 57.394972
A131: 45408.529 | B131: 57.270526
... A4189: 45411.347 | B4189: 4.233139
